2023-10-30 16:25:34,621 [ERROR] - Exception on / [GET]
Traceback (most recent call last):
  File "D:\Udacity\Azure\cd1756-Azure-Applications-project\env\lib\site-packages\sqlalchemy\engine\base.py", line 2276, in _wrap_pool_connect
    return fn()
  File "D:\Udacity\Azure\cd1756-Azure-Applications-project\env\lib\site-packages\sqlalchemy\pool\base.py", line 363, in connect
    return _ConnectionFairy._checkout(self)
  File "D:\Udacity\Azure\cd1756-Azure-Applications-project\env\lib\site-packages\sqlalchemy\pool\base.py", line 773, in _checkout
    fairy = _ConnectionRecord.checkout(pool)
  File "D:\Udacity\Azure\cd1756-Azure-Applications-project\env\lib\site-packages\sqlalchemy\pool\base.py", line 492, in checkout
    rec = pool._do_get()
  File "D:\Udacity\Azure\cd1756-Azure-Applications-project\env\lib\site-packages\sqlalchemy\pool\impl.py", line 139, in _do_get
    self._dec_overflow()
  File "D:\Udacity\Azure\cd1756-Azure-Applications-project\env\lib\site-packages\sqlalchemy\util\langhelpers.py", line 68, in __exit__
    compat.reraise(exc_type, exc_value, exc_tb)
  File "D:\Udacity\Azure\cd1756-Azure-Applications-project\env\lib\site-packages\sqlalchemy\util\compat.py", line 153, in reraise
    raise value
  File "D:\Udacity\Azure\cd1756-Azure-Applications-project\env\lib\site-packages\sqlalchemy\pool\impl.py", line 136, in _do_get
    return self._create_connection()
  File "D:\Udacity\Azure\cd1756-Azure-Applications-project\env\lib\site-packages\sqlalchemy\pool\base.py", line 308, in _create_connection
    return _ConnectionRecord(self)
  File "D:\Udacity\Azure\cd1756-Azure-Applications-project\env\lib\site-packages\sqlalchemy\pool\base.py", line 437, in __init__
    self.__connect(first_connect_check=True)
  File "D:\Udacity\Azure\cd1756-Azure-Applications-project\env\lib\site-packages\sqlalchemy\pool\base.py", line 652, in __connect
    connection = pool._invoke_creator(self)
  File "D:\Udacity\Azure\cd1756-Azure-Applications-project\env\lib\site-packages\sqlalchemy\engine\strategies.py", line 114, in connect
    return dialect.connect(*cargs, **cparams)
  File "D:\Udacity\Azure\cd1756-Azure-Applications-project\env\lib\site-packages\sqlalchemy\engine\default.py", line 489, in connect
    return self.dbapi.connect(*cargs, **cparams)
pyodbc.ProgrammingError: ('42000', "[42000] [Microsoft][ODBC Driver 17 for SQL Server][SQL Server]Cannot open server 'article-server' requested by the login. Client with IP address '103.199.33.200' is not allowed to access the server.  To enable access, use the Azure Management Portal or run sp_set_firewall_rule on the master database to create a firewall rule for this IP address or address range.  It may take up to five minutes for this change to take effect. (40615) (SQLDriverConnect); [42000] [Microsoft][ODBC Driver 17 for SQL Server][SQL Server]Cannot open server 'article-server' requested by the login. Client with IP address '103.199.33.200' is not allowed to access the server.  To enable access, use the Azure Management Portal or run sp_set_firewall_rule on the master database to create a firewall rule for this IP address or address range.  It may take up to five minutes for this change to take effect. (40615)")

The above exception was the direct cause of the following exception:

Traceback (most recent call last):
  File "D:\Udacity\Azure\cd1756-Azure-Applications-project\env\lib\site-packages\flask\app.py", line 1982, in wsgi_app
    response = self.full_dispatch_request()
  File "D:\Udacity\Azure\cd1756-Azure-Applications-project\env\lib\site-packages\flask\app.py", line 1614, in full_dispatch_request
    rv = self.handle_user_exception(e)
  File "D:\Udacity\Azure\cd1756-Azure-Applications-project\env\lib\site-packages\flask\app.py", line 1517, in handle_user_exception
    reraise(exc_type, exc_value, tb)
  File "D:\Udacity\Azure\cd1756-Azure-Applications-project\env\lib\site-packages\flask\_compat.py", line 33, in reraise
    raise value
  File "D:\Udacity\Azure\cd1756-Azure-Applications-project\env\lib\site-packages\flask\app.py", line 1612, in full_dispatch_request
    rv = self.dispatch_request()
  File "D:\Udacity\Azure\cd1756-Azure-Applications-project\env\lib\site-packages\flask\app.py", line 1598, in dispatch_request
    return self.view_functions[rule.endpoint](**req.view_args)
  File "D:\Udacity\Azure\cd1756-Azure-Applications-project\env\lib\site-packages\flask_login\utils.py", line 270, in decorated_view
    elif not current_user.is_authenticated:
  File "D:\Udacity\Azure\cd1756-Azure-Applications-project\env\lib\site-packages\werkzeug\local.py", line 348, in __getattr__
    return getattr(self._get_current_object(), name)
  File "D:\Udacity\Azure\cd1756-Azure-Applications-project\env\lib\site-packages\werkzeug\local.py", line 307, in _get_current_object
    return self.__local()
  File "D:\Udacity\Azure\cd1756-Azure-Applications-project\env\lib\site-packages\flask_login\utils.py", line 26, in <lambda>
    current_user = LocalProxy(lambda: _get_user())
  File "D:\Udacity\Azure\cd1756-Azure-Applications-project\env\lib\site-packages\flask_login\utils.py", line 346, in _get_user
    current_app.login_manager._load_user()
  File "D:\Udacity\Azure\cd1756-Azure-Applications-project\env\lib\site-packages\flask_login\login_manager.py", line 318, in _load_user
    user = self._user_callback(user_id)
  File "D:\Udacity\Azure\cd1756-Azure-Applications-project\FlaskWebProject\models.py", line 33, in load_user
    return User.query.get(int(id))
  File "D:\Udacity\Azure\cd1756-Azure-Applications-project\env\lib\site-packages\sqlalchemy\orm\query.py", line 1004, in get
    return self._get_impl(ident, loading.load_on_pk_identity)
  File "D:\Udacity\Azure\cd1756-Azure-Applications-project\env\lib\site-packages\sqlalchemy\orm\query.py", line 1116, in _get_impl
    return db_load_fn(self, primary_key_identity)
  File "D:\Udacity\Azure\cd1756-Azure-Applications-project\env\lib\site-packages\sqlalchemy\orm\loading.py", line 284, in load_on_pk_identity
    return q.one()
  File "D:\Udacity\Azure\cd1756-Azure-Applications-project\env\lib\site-packages\sqlalchemy\orm\query.py", line 3347, in one
    ret = self.one_or_none()
  File "D:\Udacity\Azure\cd1756-Azure-Applications-project\env\lib\site-packages\sqlalchemy\orm\query.py", line 3316, in one_or_none
    ret = list(self)
  File "D:\Udacity\Azure\cd1756-Azure-Applications-project\env\lib\site-packages\sqlalchemy\orm\query.py", line 3389, in __iter__
    return self._execute_and_instances(context)
  File "D:\Udacity\Azure\cd1756-Azure-Applications-project\env\lib\site-packages\sqlalchemy\orm\query.py", line 3411, in _execute_and_instances
    querycontext, self._connection_from_session, close_with_result=True
  File "D:\Udacity\Azure\cd1756-Azure-Applications-project\env\lib\site-packages\sqlalchemy\orm\query.py", line 3426, in _get_bind_args
    mapper=self._bind_mapper(), clause=querycontext.statement, **kw
  File "D:\Udacity\Azure\cd1756-Azure-Applications-project\env\lib\site-packages\sqlalchemy\orm\query.py", line 3404, in _connection_from_session
    conn = self.session.connection(**kw)
  File "D:\Udacity\Azure\cd1756-Azure-Applications-project\env\lib\site-packages\sqlalchemy\orm\session.py", line 1133, in connection
    execution_options=execution_options,
  File "D:\Udacity\Azure\cd1756-Azure-Applications-project\env\lib\site-packages\sqlalchemy\orm\session.py", line 1139, in _connection_for_bind
    engine, execution_options
  File "D:\Udacity\Azure\cd1756-Azure-Applications-project\env\lib\site-packages\sqlalchemy\orm\session.py", line 432, in _connection_for_bind
    conn = bind._contextual_connect()
  File "D:\Udacity\Azure\cd1756-Azure-Applications-project\env\lib\site-packages\sqlalchemy\engine\base.py", line 2242, in _contextual_connect
    self._wrap_pool_connect(self.pool.connect, None),
  File "D:\Udacity\Azure\cd1756-Azure-Applications-project\env\lib\site-packages\sqlalchemy\engine\base.py", line 2280, in _wrap_pool_connect
    e, dialect, self
  File "D:\Udacity\Azure\cd1756-Azure-Applications-project\env\lib\site-packages\sqlalchemy\engine\base.py", line 1547, in _handle_dbapi_exception_noconnection
    util.raise_from_cause(sqlalchemy_exception, exc_info)
  File "D:\Udacity\Azure\cd1756-Azure-Applications-project\env\lib\site-packages\sqlalchemy\util\compat.py", line 398, in raise_from_cause
    reraise(type(exception), exception, tb=exc_tb, cause=cause)
  File "D:\Udacity\Azure\cd1756-Azure-Applications-project\env\lib\site-packages\sqlalchemy\util\compat.py", line 152, in reraise
    raise value.with_traceback(tb)
  File "D:\Udacity\Azure\cd1756-Azure-Applications-project\env\lib\site-packages\sqlalchemy\engine\base.py", line 2276, in _wrap_pool_connect
    return fn()
  File "D:\Udacity\Azure\cd1756-Azure-Applications-project\env\lib\site-packages\sqlalchemy\pool\base.py", line 363, in connect
    return _ConnectionFairy._checkout(self)
  File "D:\Udacity\Azure\cd1756-Azure-Applications-project\env\lib\site-packages\sqlalchemy\pool\base.py", line 773, in _checkout
    fairy = _ConnectionRecord.checkout(pool)
  File "D:\Udacity\Azure\cd1756-Azure-Applications-project\env\lib\site-packages\sqlalchemy\pool\base.py", line 492, in checkout
    rec = pool._do_get()
  File "D:\Udacity\Azure\cd1756-Azure-Applications-project\env\lib\site-packages\sqlalchemy\pool\impl.py", line 139, in _do_get
    self._dec_overflow()
  File "D:\Udacity\Azure\cd1756-Azure-Applications-project\env\lib\site-packages\sqlalchemy\util\langhelpers.py", line 68, in __exit__
    compat.reraise(exc_type, exc_value, exc_tb)
  File "D:\Udacity\Azure\cd1756-Azure-Applications-project\env\lib\site-packages\sqlalchemy\util\compat.py", line 153, in reraise
    raise value
  File "D:\Udacity\Azure\cd1756-Azure-Applications-project\env\lib\site-packages\sqlalchemy\pool\impl.py", line 136, in _do_get
    return self._create_connection()
  File "D:\Udacity\Azure\cd1756-Azure-Applications-project\env\lib\site-packages\sqlalchemy\pool\base.py", line 308, in _create_connection
    return _ConnectionRecord(self)
  File "D:\Udacity\Azure\cd1756-Azure-Applications-project\env\lib\site-packages\sqlalchemy\pool\base.py", line 437, in __init__
    self.__connect(first_connect_check=True)
  File "D:\Udacity\Azure\cd1756-Azure-Applications-project\env\lib\site-packages\sqlalchemy\pool\base.py", line 652, in __connect
    connection = pool._invoke_creator(self)
  File "D:\Udacity\Azure\cd1756-Azure-Applications-project\env\lib\site-packages\sqlalchemy\engine\strategies.py", line 114, in connect
    return dialect.connect(*cargs, **cparams)
  File "D:\Udacity\Azure\cd1756-Azure-Applications-project\env\lib\site-packages\sqlalchemy\engine\default.py", line 489, in connect
    return self.dbapi.connect(*cargs, **cparams)
sqlalchemy.exc.ProgrammingError: (pyodbc.ProgrammingError) ('42000', "[42000] [Microsoft][ODBC Driver 17 for SQL Server][SQL Server]Cannot open server 'article-server' requested by the login. Client with IP address '103.199.33.200' is not allowed to access the server.  To enable access, use the Azure Management Portal or run sp_set_firewall_rule on the master database to create a firewall rule for this IP address or address range.  It may take up to five minutes for this change to take effect. (40615) (SQLDriverConnect); [42000] [Microsoft][ODBC Driver 17 for SQL Server][SQL Server]Cannot open server 'article-server' requested by the login. Client with IP address '103.199.33.200' is not allowed to access the server.  To enable access, use the Azure Management Portal or run sp_set_firewall_rule on the master database to create a firewall rule for this IP address or address range.  It may take up to five minutes for this change to take effect. (40615)")
(Background on this error at: http://sqlalche.me/e/f405)
2023-10-30 16:25:38,364 [ERROR] - Exception on / [GET]
Traceback (most recent call last):
  File "D:\Udacity\Azure\cd1756-Azure-Applications-project\env\lib\site-packages\sqlalchemy\engine\base.py", line 2276, in _wrap_pool_connect
    return fn()
  File "D:\Udacity\Azure\cd1756-Azure-Applications-project\env\lib\site-packages\sqlalchemy\pool\base.py", line 363, in connect
    return _ConnectionFairy._checkout(self)
  File "D:\Udacity\Azure\cd1756-Azure-Applications-project\env\lib\site-packages\sqlalchemy\pool\base.py", line 773, in _checkout
    fairy = _ConnectionRecord.checkout(pool)
  File "D:\Udacity\Azure\cd1756-Azure-Applications-project\env\lib\site-packages\sqlalchemy\pool\base.py", line 492, in checkout
    rec = pool._do_get()
  File "D:\Udacity\Azure\cd1756-Azure-Applications-project\env\lib\site-packages\sqlalchemy\pool\impl.py", line 139, in _do_get
    self._dec_overflow()
  File "D:\Udacity\Azure\cd1756-Azure-Applications-project\env\lib\site-packages\sqlalchemy\util\langhelpers.py", line 68, in __exit__
    compat.reraise(exc_type, exc_value, exc_tb)
  File "D:\Udacity\Azure\cd1756-Azure-Applications-project\env\lib\site-packages\sqlalchemy\util\compat.py", line 153, in reraise
    raise value
  File "D:\Udacity\Azure\cd1756-Azure-Applications-project\env\lib\site-packages\sqlalchemy\pool\impl.py", line 136, in _do_get
    return self._create_connection()
  File "D:\Udacity\Azure\cd1756-Azure-Applications-project\env\lib\site-packages\sqlalchemy\pool\base.py", line 308, in _create_connection
    return _ConnectionRecord(self)
  File "D:\Udacity\Azure\cd1756-Azure-Applications-project\env\lib\site-packages\sqlalchemy\pool\base.py", line 437, in __init__
    self.__connect(first_connect_check=True)
  File "D:\Udacity\Azure\cd1756-Azure-Applications-project\env\lib\site-packages\sqlalchemy\pool\base.py", line 652, in __connect
    connection = pool._invoke_creator(self)
  File "D:\Udacity\Azure\cd1756-Azure-Applications-project\env\lib\site-packages\sqlalchemy\engine\strategies.py", line 114, in connect
    return dialect.connect(*cargs, **cparams)
  File "D:\Udacity\Azure\cd1756-Azure-Applications-project\env\lib\site-packages\sqlalchemy\engine\default.py", line 489, in connect
    return self.dbapi.connect(*cargs, **cparams)
pyodbc.ProgrammingError: ('42000', "[42000] [Microsoft][ODBC Driver 17 for SQL Server][SQL Server]Cannot open server 'article-server' requested by the login. Client with IP address '103.199.33.200' is not allowed to access the server.  To enable access, use the Azure Management Portal or run sp_set_firewall_rule on the master database to create a firewall rule for this IP address or address range.  It may take up to five minutes for this change to take effect. (40615) (SQLDriverConnect); [42000] [Microsoft][ODBC Driver 17 for SQL Server][SQL Server]Cannot open server 'article-server' requested by the login. Client with IP address '103.199.33.200' is not allowed to access the server.  To enable access, use the Azure Management Portal or run sp_set_firewall_rule on the master database to create a firewall rule for this IP address or address range.  It may take up to five minutes for this change to take effect. (40615)")

The above exception was the direct cause of the following exception:

Traceback (most recent call last):
  File "D:\Udacity\Azure\cd1756-Azure-Applications-project\env\lib\site-packages\flask\app.py", line 1982, in wsgi_app
    response = self.full_dispatch_request()
  File "D:\Udacity\Azure\cd1756-Azure-Applications-project\env\lib\site-packages\flask\app.py", line 1614, in full_dispatch_request
    rv = self.handle_user_exception(e)
  File "D:\Udacity\Azure\cd1756-Azure-Applications-project\env\lib\site-packages\flask\app.py", line 1517, in handle_user_exception
    reraise(exc_type, exc_value, tb)
  File "D:\Udacity\Azure\cd1756-Azure-Applications-project\env\lib\site-packages\flask\_compat.py", line 33, in reraise
    raise value
  File "D:\Udacity\Azure\cd1756-Azure-Applications-project\env\lib\site-packages\flask\app.py", line 1612, in full_dispatch_request
    rv = self.dispatch_request()
  File "D:\Udacity\Azure\cd1756-Azure-Applications-project\env\lib\site-packages\flask\app.py", line 1598, in dispatch_request
    return self.view_functions[rule.endpoint](**req.view_args)
  File "D:\Udacity\Azure\cd1756-Azure-Applications-project\env\lib\site-packages\flask_login\utils.py", line 270, in decorated_view
    elif not current_user.is_authenticated:
  File "D:\Udacity\Azure\cd1756-Azure-Applications-project\env\lib\site-packages\werkzeug\local.py", line 348, in __getattr__
    return getattr(self._get_current_object(), name)
  File "D:\Udacity\Azure\cd1756-Azure-Applications-project\env\lib\site-packages\werkzeug\local.py", line 307, in _get_current_object
    return self.__local()
  File "D:\Udacity\Azure\cd1756-Azure-Applications-project\env\lib\site-packages\flask_login\utils.py", line 26, in <lambda>
    current_user = LocalProxy(lambda: _get_user())
  File "D:\Udacity\Azure\cd1756-Azure-Applications-project\env\lib\site-packages\flask_login\utils.py", line 346, in _get_user
    current_app.login_manager._load_user()
  File "D:\Udacity\Azure\cd1756-Azure-Applications-project\env\lib\site-packages\flask_login\login_manager.py", line 318, in _load_user
    user = self._user_callback(user_id)
  File "D:\Udacity\Azure\cd1756-Azure-Applications-project\FlaskWebProject\models.py", line 33, in load_user
    return User.query.get(int(id))
  File "D:\Udacity\Azure\cd1756-Azure-Applications-project\env\lib\site-packages\sqlalchemy\orm\query.py", line 1004, in get
    return self._get_impl(ident, loading.load_on_pk_identity)
  File "D:\Udacity\Azure\cd1756-Azure-Applications-project\env\lib\site-packages\sqlalchemy\orm\query.py", line 1116, in _get_impl
    return db_load_fn(self, primary_key_identity)
  File "D:\Udacity\Azure\cd1756-Azure-Applications-project\env\lib\site-packages\sqlalchemy\orm\loading.py", line 284, in load_on_pk_identity
    return q.one()
  File "D:\Udacity\Azure\cd1756-Azure-Applications-project\env\lib\site-packages\sqlalchemy\orm\query.py", line 3347, in one
    ret = self.one_or_none()
  File "D:\Udacity\Azure\cd1756-Azure-Applications-project\env\lib\site-packages\sqlalchemy\orm\query.py", line 3316, in one_or_none
    ret = list(self)
  File "D:\Udacity\Azure\cd1756-Azure-Applications-project\env\lib\site-packages\sqlalchemy\orm\query.py", line 3389, in __iter__
    return self._execute_and_instances(context)
  File "D:\Udacity\Azure\cd1756-Azure-Applications-project\env\lib\site-packages\sqlalchemy\orm\query.py", line 3411, in _execute_and_instances
    querycontext, self._connection_from_session, close_with_result=True
  File "D:\Udacity\Azure\cd1756-Azure-Applications-project\env\lib\site-packages\sqlalchemy\orm\query.py", line 3426, in _get_bind_args
    mapper=self._bind_mapper(), clause=querycontext.statement, **kw
  File "D:\Udacity\Azure\cd1756-Azure-Applications-project\env\lib\site-packages\sqlalchemy\orm\query.py", line 3404, in _connection_from_session
    conn = self.session.connection(**kw)
  File "D:\Udacity\Azure\cd1756-Azure-Applications-project\env\lib\site-packages\sqlalchemy\orm\session.py", line 1133, in connection
    execution_options=execution_options,
  File "D:\Udacity\Azure\cd1756-Azure-Applications-project\env\lib\site-packages\sqlalchemy\orm\session.py", line 1139, in _connection_for_bind
    engine, execution_options
  File "D:\Udacity\Azure\cd1756-Azure-Applications-project\env\lib\site-packages\sqlalchemy\orm\session.py", line 432, in _connection_for_bind
    conn = bind._contextual_connect()
  File "D:\Udacity\Azure\cd1756-Azure-Applications-project\env\lib\site-packages\sqlalchemy\engine\base.py", line 2242, in _contextual_connect
    self._wrap_pool_connect(self.pool.connect, None),
  File "D:\Udacity\Azure\cd1756-Azure-Applications-project\env\lib\site-packages\sqlalchemy\engine\base.py", line 2280, in _wrap_pool_connect
    e, dialect, self
  File "D:\Udacity\Azure\cd1756-Azure-Applications-project\env\lib\site-packages\sqlalchemy\engine\base.py", line 1547, in _handle_dbapi_exception_noconnection
    util.raise_from_cause(sqlalchemy_exception, exc_info)
  File "D:\Udacity\Azure\cd1756-Azure-Applications-project\env\lib\site-packages\sqlalchemy\util\compat.py", line 398, in raise_from_cause
    reraise(type(exception), exception, tb=exc_tb, cause=cause)
  File "D:\Udacity\Azure\cd1756-Azure-Applications-project\env\lib\site-packages\sqlalchemy\util\compat.py", line 152, in reraise
    raise value.with_traceback(tb)
  File "D:\Udacity\Azure\cd1756-Azure-Applications-project\env\lib\site-packages\sqlalchemy\engine\base.py", line 2276, in _wrap_pool_connect
    return fn()
  File "D:\Udacity\Azure\cd1756-Azure-Applications-project\env\lib\site-packages\sqlalchemy\pool\base.py", line 363, in connect
    return _ConnectionFairy._checkout(self)
  File "D:\Udacity\Azure\cd1756-Azure-Applications-project\env\lib\site-packages\sqlalchemy\pool\base.py", line 773, in _checkout
    fairy = _ConnectionRecord.checkout(pool)
  File "D:\Udacity\Azure\cd1756-Azure-Applications-project\env\lib\site-packages\sqlalchemy\pool\base.py", line 492, in checkout
    rec = pool._do_get()
  File "D:\Udacity\Azure\cd1756-Azure-Applications-project\env\lib\site-packages\sqlalchemy\pool\impl.py", line 139, in _do_get
    self._dec_overflow()
  File "D:\Udacity\Azure\cd1756-Azure-Applications-project\env\lib\site-packages\sqlalchemy\util\langhelpers.py", line 68, in __exit__
    compat.reraise(exc_type, exc_value, exc_tb)
  File "D:\Udacity\Azure\cd1756-Azure-Applications-project\env\lib\site-packages\sqlalchemy\util\compat.py", line 153, in reraise
    raise value
  File "D:\Udacity\Azure\cd1756-Azure-Applications-project\env\lib\site-packages\sqlalchemy\pool\impl.py", line 136, in _do_get
    return self._create_connection()
  File "D:\Udacity\Azure\cd1756-Azure-Applications-project\env\lib\site-packages\sqlalchemy\pool\base.py", line 308, in _create_connection
    return _ConnectionRecord(self)
  File "D:\Udacity\Azure\cd1756-Azure-Applications-project\env\lib\site-packages\sqlalchemy\pool\base.py", line 437, in __init__
    self.__connect(first_connect_check=True)
  File "D:\Udacity\Azure\cd1756-Azure-Applications-project\env\lib\site-packages\sqlalchemy\pool\base.py", line 652, in __connect
    connection = pool._invoke_creator(self)
  File "D:\Udacity\Azure\cd1756-Azure-Applications-project\env\lib\site-packages\sqlalchemy\engine\strategies.py", line 114, in connect
    return dialect.connect(*cargs, **cparams)
  File "D:\Udacity\Azure\cd1756-Azure-Applications-project\env\lib\site-packages\sqlalchemy\engine\default.py", line 489, in connect
    return self.dbapi.connect(*cargs, **cparams)
sqlalchemy.exc.ProgrammingError: (pyodbc.ProgrammingError) ('42000', "[42000] [Microsoft][ODBC Driver 17 for SQL Server][SQL Server]Cannot open server 'article-server' requested by the login. Client with IP address '103.199.33.200' is not allowed to access the server.  To enable access, use the Azure Management Portal or run sp_set_firewall_rule on the master database to create a firewall rule for this IP address or address range.  It may take up to five minutes for this change to take effect. (40615) (SQLDriverConnect); [42000] [Microsoft][ODBC Driver 17 for SQL Server][SQL Server]Cannot open server 'article-server' requested by the login. Client with IP address '103.199.33.200' is not allowed to access the server.  To enable access, use the Azure Management Portal or run sp_set_firewall_rule on the master database to create a firewall rule for this IP address or address range.  It may take up to five minutes for this change to take effect. (40615)")
(Background on this error at: http://sqlalche.me/e/f405)
2023-10-30 16:25:42,795 [ERROR] - Exception on / [GET]
Traceback (most recent call last):
  File "D:\Udacity\Azure\cd1756-Azure-Applications-project\env\lib\site-packages\sqlalchemy\engine\base.py", line 2276, in _wrap_pool_connect
    return fn()
  File "D:\Udacity\Azure\cd1756-Azure-Applications-project\env\lib\site-packages\sqlalchemy\pool\base.py", line 363, in connect
    return _ConnectionFairy._checkout(self)
  File "D:\Udacity\Azure\cd1756-Azure-Applications-project\env\lib\site-packages\sqlalchemy\pool\base.py", line 773, in _checkout
    fairy = _ConnectionRecord.checkout(pool)
  File "D:\Udacity\Azure\cd1756-Azure-Applications-project\env\lib\site-packages\sqlalchemy\pool\base.py", line 492, in checkout
    rec = pool._do_get()
  File "D:\Udacity\Azure\cd1756-Azure-Applications-project\env\lib\site-packages\sqlalchemy\pool\impl.py", line 139, in _do_get
    self._dec_overflow()
  File "D:\Udacity\Azure\cd1756-Azure-Applications-project\env\lib\site-packages\sqlalchemy\util\langhelpers.py", line 68, in __exit__
    compat.reraise(exc_type, exc_value, exc_tb)
  File "D:\Udacity\Azure\cd1756-Azure-Applications-project\env\lib\site-packages\sqlalchemy\util\compat.py", line 153, in reraise
    raise value
  File "D:\Udacity\Azure\cd1756-Azure-Applications-project\env\lib\site-packages\sqlalchemy\pool\impl.py", line 136, in _do_get
    return self._create_connection()
  File "D:\Udacity\Azure\cd1756-Azure-Applications-project\env\lib\site-packages\sqlalchemy\pool\base.py", line 308, in _create_connection
    return _ConnectionRecord(self)
  File "D:\Udacity\Azure\cd1756-Azure-Applications-project\env\lib\site-packages\sqlalchemy\pool\base.py", line 437, in __init__
    self.__connect(first_connect_check=True)
  File "D:\Udacity\Azure\cd1756-Azure-Applications-project\env\lib\site-packages\sqlalchemy\pool\base.py", line 652, in __connect
    connection = pool._invoke_creator(self)
  File "D:\Udacity\Azure\cd1756-Azure-Applications-project\env\lib\site-packages\sqlalchemy\engine\strategies.py", line 114, in connect
    return dialect.connect(*cargs, **cparams)
  File "D:\Udacity\Azure\cd1756-Azure-Applications-project\env\lib\site-packages\sqlalchemy\engine\default.py", line 489, in connect
    return self.dbapi.connect(*cargs, **cparams)
pyodbc.ProgrammingError: ('42000', "[42000] [Microsoft][ODBC Driver 17 for SQL Server][SQL Server]Cannot open server 'article-server' requested by the login. Client with IP address '103.199.33.200' is not allowed to access the server.  To enable access, use the Azure Management Portal or run sp_set_firewall_rule on the master database to create a firewall rule for this IP address or address range.  It may take up to five minutes for this change to take effect. (40615) (SQLDriverConnect); [42000] [Microsoft][ODBC Driver 17 for SQL Server][SQL Server]Cannot open server 'article-server' requested by the login. Client with IP address '103.199.33.200' is not allowed to access the server.  To enable access, use the Azure Management Portal or run sp_set_firewall_rule on the master database to create a firewall rule for this IP address or address range.  It may take up to five minutes for this change to take effect. (40615)")

The above exception was the direct cause of the following exception:

Traceback (most recent call last):
  File "D:\Udacity\Azure\cd1756-Azure-Applications-project\env\lib\site-packages\flask\app.py", line 1982, in wsgi_app
    response = self.full_dispatch_request()
  File "D:\Udacity\Azure\cd1756-Azure-Applications-project\env\lib\site-packages\flask\app.py", line 1614, in full_dispatch_request
    rv = self.handle_user_exception(e)
  File "D:\Udacity\Azure\cd1756-Azure-Applications-project\env\lib\site-packages\flask\app.py", line 1517, in handle_user_exception
    reraise(exc_type, exc_value, tb)
  File "D:\Udacity\Azure\cd1756-Azure-Applications-project\env\lib\site-packages\flask\_compat.py", line 33, in reraise
    raise value
  File "D:\Udacity\Azure\cd1756-Azure-Applications-project\env\lib\site-packages\flask\app.py", line 1612, in full_dispatch_request
    rv = self.dispatch_request()
  File "D:\Udacity\Azure\cd1756-Azure-Applications-project\env\lib\site-packages\flask\app.py", line 1598, in dispatch_request
    return self.view_functions[rule.endpoint](**req.view_args)
  File "D:\Udacity\Azure\cd1756-Azure-Applications-project\env\lib\site-packages\flask_login\utils.py", line 270, in decorated_view
    elif not current_user.is_authenticated:
  File "D:\Udacity\Azure\cd1756-Azure-Applications-project\env\lib\site-packages\werkzeug\local.py", line 348, in __getattr__
    return getattr(self._get_current_object(), name)
  File "D:\Udacity\Azure\cd1756-Azure-Applications-project\env\lib\site-packages\werkzeug\local.py", line 307, in _get_current_object
    return self.__local()
  File "D:\Udacity\Azure\cd1756-Azure-Applications-project\env\lib\site-packages\flask_login\utils.py", line 26, in <lambda>
    current_user = LocalProxy(lambda: _get_user())
  File "D:\Udacity\Azure\cd1756-Azure-Applications-project\env\lib\site-packages\flask_login\utils.py", line 346, in _get_user
    current_app.login_manager._load_user()
  File "D:\Udacity\Azure\cd1756-Azure-Applications-project\env\lib\site-packages\flask_login\login_manager.py", line 318, in _load_user
    user = self._user_callback(user_id)
  File "D:\Udacity\Azure\cd1756-Azure-Applications-project\FlaskWebProject\models.py", line 33, in load_user
    return User.query.get(int(id))
  File "D:\Udacity\Azure\cd1756-Azure-Applications-project\env\lib\site-packages\sqlalchemy\orm\query.py", line 1004, in get
    return self._get_impl(ident, loading.load_on_pk_identity)
  File "D:\Udacity\Azure\cd1756-Azure-Applications-project\env\lib\site-packages\sqlalchemy\orm\query.py", line 1116, in _get_impl
    return db_load_fn(self, primary_key_identity)
  File "D:\Udacity\Azure\cd1756-Azure-Applications-project\env\lib\site-packages\sqlalchemy\orm\loading.py", line 284, in load_on_pk_identity
    return q.one()
  File "D:\Udacity\Azure\cd1756-Azure-Applications-project\env\lib\site-packages\sqlalchemy\orm\query.py", line 3347, in one
    ret = self.one_or_none()
  File "D:\Udacity\Azure\cd1756-Azure-Applications-project\env\lib\site-packages\sqlalchemy\orm\query.py", line 3316, in one_or_none
    ret = list(self)
  File "D:\Udacity\Azure\cd1756-Azure-Applications-project\env\lib\site-packages\sqlalchemy\orm\query.py", line 3389, in __iter__
    return self._execute_and_instances(context)
  File "D:\Udacity\Azure\cd1756-Azure-Applications-project\env\lib\site-packages\sqlalchemy\orm\query.py", line 3411, in _execute_and_instances
    querycontext, self._connection_from_session, close_with_result=True
  File "D:\Udacity\Azure\cd1756-Azure-Applications-project\env\lib\site-packages\sqlalchemy\orm\query.py", line 3426, in _get_bind_args
    mapper=self._bind_mapper(), clause=querycontext.statement, **kw
  File "D:\Udacity\Azure\cd1756-Azure-Applications-project\env\lib\site-packages\sqlalchemy\orm\query.py", line 3404, in _connection_from_session
    conn = self.session.connection(**kw)
  File "D:\Udacity\Azure\cd1756-Azure-Applications-project\env\lib\site-packages\sqlalchemy\orm\session.py", line 1133, in connection
    execution_options=execution_options,
  File "D:\Udacity\Azure\cd1756-Azure-Applications-project\env\lib\site-packages\sqlalchemy\orm\session.py", line 1139, in _connection_for_bind
    engine, execution_options
  File "D:\Udacity\Azure\cd1756-Azure-Applications-project\env\lib\site-packages\sqlalchemy\orm\session.py", line 432, in _connection_for_bind
    conn = bind._contextual_connect()
  File "D:\Udacity\Azure\cd1756-Azure-Applications-project\env\lib\site-packages\sqlalchemy\engine\base.py", line 2242, in _contextual_connect
    self._wrap_pool_connect(self.pool.connect, None),
  File "D:\Udacity\Azure\cd1756-Azure-Applications-project\env\lib\site-packages\sqlalchemy\engine\base.py", line 2280, in _wrap_pool_connect
    e, dialect, self
  File "D:\Udacity\Azure\cd1756-Azure-Applications-project\env\lib\site-packages\sqlalchemy\engine\base.py", line 1547, in _handle_dbapi_exception_noconnection
    util.raise_from_cause(sqlalchemy_exception, exc_info)
  File "D:\Udacity\Azure\cd1756-Azure-Applications-project\env\lib\site-packages\sqlalchemy\util\compat.py", line 398, in raise_from_cause
    reraise(type(exception), exception, tb=exc_tb, cause=cause)
  File "D:\Udacity\Azure\cd1756-Azure-Applications-project\env\lib\site-packages\sqlalchemy\util\compat.py", line 152, in reraise
    raise value.with_traceback(tb)
  File "D:\Udacity\Azure\cd1756-Azure-Applications-project\env\lib\site-packages\sqlalchemy\engine\base.py", line 2276, in _wrap_pool_connect
    return fn()
  File "D:\Udacity\Azure\cd1756-Azure-Applications-project\env\lib\site-packages\sqlalchemy\pool\base.py", line 363, in connect
    return _ConnectionFairy._checkout(self)
  File "D:\Udacity\Azure\cd1756-Azure-Applications-project\env\lib\site-packages\sqlalchemy\pool\base.py", line 773, in _checkout
    fairy = _ConnectionRecord.checkout(pool)
  File "D:\Udacity\Azure\cd1756-Azure-Applications-project\env\lib\site-packages\sqlalchemy\pool\base.py", line 492, in checkout
    rec = pool._do_get()
  File "D:\Udacity\Azure\cd1756-Azure-Applications-project\env\lib\site-packages\sqlalchemy\pool\impl.py", line 139, in _do_get
    self._dec_overflow()
  File "D:\Udacity\Azure\cd1756-Azure-Applications-project\env\lib\site-packages\sqlalchemy\util\langhelpers.py", line 68, in __exit__
    compat.reraise(exc_type, exc_value, exc_tb)
  File "D:\Udacity\Azure\cd1756-Azure-Applications-project\env\lib\site-packages\sqlalchemy\util\compat.py", line 153, in reraise
    raise value
  File "D:\Udacity\Azure\cd1756-Azure-Applications-project\env\lib\site-packages\sqlalchemy\pool\impl.py", line 136, in _do_get
    return self._create_connection()
  File "D:\Udacity\Azure\cd1756-Azure-Applications-project\env\lib\site-packages\sqlalchemy\pool\base.py", line 308, in _create_connection
    return _ConnectionRecord(self)
  File "D:\Udacity\Azure\cd1756-Azure-Applications-project\env\lib\site-packages\sqlalchemy\pool\base.py", line 437, in __init__
    self.__connect(first_connect_check=True)
  File "D:\Udacity\Azure\cd1756-Azure-Applications-project\env\lib\site-packages\sqlalchemy\pool\base.py", line 652, in __connect
    connection = pool._invoke_creator(self)
  File "D:\Udacity\Azure\cd1756-Azure-Applications-project\env\lib\site-packages\sqlalchemy\engine\strategies.py", line 114, in connect
    return dialect.connect(*cargs, **cparams)
  File "D:\Udacity\Azure\cd1756-Azure-Applications-project\env\lib\site-packages\sqlalchemy\engine\default.py", line 489, in connect
    return self.dbapi.connect(*cargs, **cparams)
sqlalchemy.exc.ProgrammingError: (pyodbc.ProgrammingError) ('42000', "[42000] [Microsoft][ODBC Driver 17 for SQL Server][SQL Server]Cannot open server 'article-server' requested by the login. Client with IP address '103.199.33.200' is not allowed to access the server.  To enable access, use the Azure Management Portal or run sp_set_firewall_rule on the master database to create a firewall rule for this IP address or address range.  It may take up to five minutes for this change to take effect. (40615) (SQLDriverConnect); [42000] [Microsoft][ODBC Driver 17 for SQL Server][SQL Server]Cannot open server 'article-server' requested by the login. Client with IP address '103.199.33.200' is not allowed to access the server.  To enable access, use the Azure Management Portal or run sp_set_firewall_rule on the master database to create a firewall rule for this IP address or address range.  It may take up to five minutes for this change to take effect. (40615)")
(Background on this error at: http://sqlalche.me/e/f405)
2023-10-30 16:25:46,292 [ERROR] - Exception on / [GET]
Traceback (most recent call last):
  File "D:\Udacity\Azure\cd1756-Azure-Applications-project\env\lib\site-packages\sqlalchemy\engine\base.py", line 2276, in _wrap_pool_connect
    return fn()
  File "D:\Udacity\Azure\cd1756-Azure-Applications-project\env\lib\site-packages\sqlalchemy\pool\base.py", line 363, in connect
    return _ConnectionFairy._checkout(self)
  File "D:\Udacity\Azure\cd1756-Azure-Applications-project\env\lib\site-packages\sqlalchemy\pool\base.py", line 773, in _checkout
    fairy = _ConnectionRecord.checkout(pool)
  File "D:\Udacity\Azure\cd1756-Azure-Applications-project\env\lib\site-packages\sqlalchemy\pool\base.py", line 492, in checkout
    rec = pool._do_get()
  File "D:\Udacity\Azure\cd1756-Azure-Applications-project\env\lib\site-packages\sqlalchemy\pool\impl.py", line 139, in _do_get
    self._dec_overflow()
  File "D:\Udacity\Azure\cd1756-Azure-Applications-project\env\lib\site-packages\sqlalchemy\util\langhelpers.py", line 68, in __exit__
    compat.reraise(exc_type, exc_value, exc_tb)
  File "D:\Udacity\Azure\cd1756-Azure-Applications-project\env\lib\site-packages\sqlalchemy\util\compat.py", line 153, in reraise
    raise value
  File "D:\Udacity\Azure\cd1756-Azure-Applications-project\env\lib\site-packages\sqlalchemy\pool\impl.py", line 136, in _do_get
    return self._create_connection()
  File "D:\Udacity\Azure\cd1756-Azure-Applications-project\env\lib\site-packages\sqlalchemy\pool\base.py", line 308, in _create_connection
    return _ConnectionRecord(self)
  File "D:\Udacity\Azure\cd1756-Azure-Applications-project\env\lib\site-packages\sqlalchemy\pool\base.py", line 437, in __init__
    self.__connect(first_connect_check=True)
  File "D:\Udacity\Azure\cd1756-Azure-Applications-project\env\lib\site-packages\sqlalchemy\pool\base.py", line 652, in __connect
    connection = pool._invoke_creator(self)
  File "D:\Udacity\Azure\cd1756-Azure-Applications-project\env\lib\site-packages\sqlalchemy\engine\strategies.py", line 114, in connect
    return dialect.connect(*cargs, **cparams)
  File "D:\Udacity\Azure\cd1756-Azure-Applications-project\env\lib\site-packages\sqlalchemy\engine\default.py", line 489, in connect
    return self.dbapi.connect(*cargs, **cparams)
pyodbc.ProgrammingError: ('42000', "[42000] [Microsoft][ODBC Driver 17 for SQL Server][SQL Server]Cannot open server 'article-server' requested by the login. Client with IP address '103.199.33.200' is not allowed to access the server.  To enable access, use the Azure Management Portal or run sp_set_firewall_rule on the master database to create a firewall rule for this IP address or address range.  It may take up to five minutes for this change to take effect. (40615) (SQLDriverConnect); [42000] [Microsoft][ODBC Driver 17 for SQL Server][SQL Server]Cannot open server 'article-server' requested by the login. Client with IP address '103.199.33.200' is not allowed to access the server.  To enable access, use the Azure Management Portal or run sp_set_firewall_rule on the master database to create a firewall rule for this IP address or address range.  It may take up to five minutes for this change to take effect. (40615)")

The above exception was the direct cause of the following exception:

Traceback (most recent call last):
  File "D:\Udacity\Azure\cd1756-Azure-Applications-project\env\lib\site-packages\flask\app.py", line 1982, in wsgi_app
    response = self.full_dispatch_request()
  File "D:\Udacity\Azure\cd1756-Azure-Applications-project\env\lib\site-packages\flask\app.py", line 1614, in full_dispatch_request
    rv = self.handle_user_exception(e)
  File "D:\Udacity\Azure\cd1756-Azure-Applications-project\env\lib\site-packages\flask\app.py", line 1517, in handle_user_exception
    reraise(exc_type, exc_value, tb)
  File "D:\Udacity\Azure\cd1756-Azure-Applications-project\env\lib\site-packages\flask\_compat.py", line 33, in reraise
    raise value
  File "D:\Udacity\Azure\cd1756-Azure-Applications-project\env\lib\site-packages\flask\app.py", line 1612, in full_dispatch_request
    rv = self.dispatch_request()
  File "D:\Udacity\Azure\cd1756-Azure-Applications-project\env\lib\site-packages\flask\app.py", line 1598, in dispatch_request
    return self.view_functions[rule.endpoint](**req.view_args)
  File "D:\Udacity\Azure\cd1756-Azure-Applications-project\env\lib\site-packages\flask_login\utils.py", line 270, in decorated_view
    elif not current_user.is_authenticated:
  File "D:\Udacity\Azure\cd1756-Azure-Applications-project\env\lib\site-packages\werkzeug\local.py", line 348, in __getattr__
    return getattr(self._get_current_object(), name)
  File "D:\Udacity\Azure\cd1756-Azure-Applications-project\env\lib\site-packages\werkzeug\local.py", line 307, in _get_current_object
    return self.__local()
  File "D:\Udacity\Azure\cd1756-Azure-Applications-project\env\lib\site-packages\flask_login\utils.py", line 26, in <lambda>
    current_user = LocalProxy(lambda: _get_user())
  File "D:\Udacity\Azure\cd1756-Azure-Applications-project\env\lib\site-packages\flask_login\utils.py", line 346, in _get_user
    current_app.login_manager._load_user()
  File "D:\Udacity\Azure\cd1756-Azure-Applications-project\env\lib\site-packages\flask_login\login_manager.py", line 318, in _load_user
    user = self._user_callback(user_id)
  File "D:\Udacity\Azure\cd1756-Azure-Applications-project\FlaskWebProject\models.py", line 33, in load_user
    return User.query.get(int(id))
  File "D:\Udacity\Azure\cd1756-Azure-Applications-project\env\lib\site-packages\sqlalchemy\orm\query.py", line 1004, in get
    return self._get_impl(ident, loading.load_on_pk_identity)
  File "D:\Udacity\Azure\cd1756-Azure-Applications-project\env\lib\site-packages\sqlalchemy\orm\query.py", line 1116, in _get_impl
    return db_load_fn(self, primary_key_identity)
  File "D:\Udacity\Azure\cd1756-Azure-Applications-project\env\lib\site-packages\sqlalchemy\orm\loading.py", line 284, in load_on_pk_identity
    return q.one()
  File "D:\Udacity\Azure\cd1756-Azure-Applications-project\env\lib\site-packages\sqlalchemy\orm\query.py", line 3347, in one
    ret = self.one_or_none()
  File "D:\Udacity\Azure\cd1756-Azure-Applications-project\env\lib\site-packages\sqlalchemy\orm\query.py", line 3316, in one_or_none
    ret = list(self)
  File "D:\Udacity\Azure\cd1756-Azure-Applications-project\env\lib\site-packages\sqlalchemy\orm\query.py", line 3389, in __iter__
    return self._execute_and_instances(context)
  File "D:\Udacity\Azure\cd1756-Azure-Applications-project\env\lib\site-packages\sqlalchemy\orm\query.py", line 3411, in _execute_and_instances
    querycontext, self._connection_from_session, close_with_result=True
  File "D:\Udacity\Azure\cd1756-Azure-Applications-project\env\lib\site-packages\sqlalchemy\orm\query.py", line 3426, in _get_bind_args
    mapper=self._bind_mapper(), clause=querycontext.statement, **kw
  File "D:\Udacity\Azure\cd1756-Azure-Applications-project\env\lib\site-packages\sqlalchemy\orm\query.py", line 3404, in _connection_from_session
    conn = self.session.connection(**kw)
  File "D:\Udacity\Azure\cd1756-Azure-Applications-project\env\lib\site-packages\sqlalchemy\orm\session.py", line 1133, in connection
    execution_options=execution_options,
  File "D:\Udacity\Azure\cd1756-Azure-Applications-project\env\lib\site-packages\sqlalchemy\orm\session.py", line 1139, in _connection_for_bind
    engine, execution_options
  File "D:\Udacity\Azure\cd1756-Azure-Applications-project\env\lib\site-packages\sqlalchemy\orm\session.py", line 432, in _connection_for_bind
    conn = bind._contextual_connect()
  File "D:\Udacity\Azure\cd1756-Azure-Applications-project\env\lib\site-packages\sqlalchemy\engine\base.py", line 2242, in _contextual_connect
    self._wrap_pool_connect(self.pool.connect, None),
  File "D:\Udacity\Azure\cd1756-Azure-Applications-project\env\lib\site-packages\sqlalchemy\engine\base.py", line 2280, in _wrap_pool_connect
    e, dialect, self
  File "D:\Udacity\Azure\cd1756-Azure-Applications-project\env\lib\site-packages\sqlalchemy\engine\base.py", line 1547, in _handle_dbapi_exception_noconnection
    util.raise_from_cause(sqlalchemy_exception, exc_info)
  File "D:\Udacity\Azure\cd1756-Azure-Applications-project\env\lib\site-packages\sqlalchemy\util\compat.py", line 398, in raise_from_cause
    reraise(type(exception), exception, tb=exc_tb, cause=cause)
  File "D:\Udacity\Azure\cd1756-Azure-Applications-project\env\lib\site-packages\sqlalchemy\util\compat.py", line 152, in reraise
    raise value.with_traceback(tb)
  File "D:\Udacity\Azure\cd1756-Azure-Applications-project\env\lib\site-packages\sqlalchemy\engine\base.py", line 2276, in _wrap_pool_connect
    return fn()
  File "D:\Udacity\Azure\cd1756-Azure-Applications-project\env\lib\site-packages\sqlalchemy\pool\base.py", line 363, in connect
    return _ConnectionFairy._checkout(self)
  File "D:\Udacity\Azure\cd1756-Azure-Applications-project\env\lib\site-packages\sqlalchemy\pool\base.py", line 773, in _checkout
    fairy = _ConnectionRecord.checkout(pool)
  File "D:\Udacity\Azure\cd1756-Azure-Applications-project\env\lib\site-packages\sqlalchemy\pool\base.py", line 492, in checkout
    rec = pool._do_get()
  File "D:\Udacity\Azure\cd1756-Azure-Applications-project\env\lib\site-packages\sqlalchemy\pool\impl.py", line 139, in _do_get
    self._dec_overflow()
  File "D:\Udacity\Azure\cd1756-Azure-Applications-project\env\lib\site-packages\sqlalchemy\util\langhelpers.py", line 68, in __exit__
    compat.reraise(exc_type, exc_value, exc_tb)
  File "D:\Udacity\Azure\cd1756-Azure-Applications-project\env\lib\site-packages\sqlalchemy\util\compat.py", line 153, in reraise
    raise value
  File "D:\Udacity\Azure\cd1756-Azure-Applications-project\env\lib\site-packages\sqlalchemy\pool\impl.py", line 136, in _do_get
    return self._create_connection()
  File "D:\Udacity\Azure\cd1756-Azure-Applications-project\env\lib\site-packages\sqlalchemy\pool\base.py", line 308, in _create_connection
    return _ConnectionRecord(self)
  File "D:\Udacity\Azure\cd1756-Azure-Applications-project\env\lib\site-packages\sqlalchemy\pool\base.py", line 437, in __init__
    self.__connect(first_connect_check=True)
  File "D:\Udacity\Azure\cd1756-Azure-Applications-project\env\lib\site-packages\sqlalchemy\pool\base.py", line 652, in __connect
    connection = pool._invoke_creator(self)
  File "D:\Udacity\Azure\cd1756-Azure-Applications-project\env\lib\site-packages\sqlalchemy\engine\strategies.py", line 114, in connect
    return dialect.connect(*cargs, **cparams)
  File "D:\Udacity\Azure\cd1756-Azure-Applications-project\env\lib\site-packages\sqlalchemy\engine\default.py", line 489, in connect
    return self.dbapi.connect(*cargs, **cparams)
sqlalchemy.exc.ProgrammingError: (pyodbc.ProgrammingError) ('42000', "[42000] [Microsoft][ODBC Driver 17 for SQL Server][SQL Server]Cannot open server 'article-server' requested by the login. Client with IP address '103.199.33.200' is not allowed to access the server.  To enable access, use the Azure Management Portal or run sp_set_firewall_rule on the master database to create a firewall rule for this IP address or address range.  It may take up to five minutes for this change to take effect. (40615) (SQLDriverConnect); [42000] [Microsoft][ODBC Driver 17 for SQL Server][SQL Server]Cannot open server 'article-server' requested by the login. Client with IP address '103.199.33.200' is not allowed to access the server.  To enable access, use the Azure Management Portal or run sp_set_firewall_rule on the master database to create a firewall rule for this IP address or address range.  It may take up to five minutes for this change to take effect. (40615)")
(Background on this error at: http://sqlalche.me/e/f405)
2023-10-30 16:25:50,272 [ERROR] - Exception on / [GET]
Traceback (most recent call last):
  File "D:\Udacity\Azure\cd1756-Azure-Applications-project\env\lib\site-packages\sqlalchemy\engine\base.py", line 2276, in _wrap_pool_connect
    return fn()
  File "D:\Udacity\Azure\cd1756-Azure-Applications-project\env\lib\site-packages\sqlalchemy\pool\base.py", line 363, in connect
    return _ConnectionFairy._checkout(self)
  File "D:\Udacity\Azure\cd1756-Azure-Applications-project\env\lib\site-packages\sqlalchemy\pool\base.py", line 773, in _checkout
    fairy = _ConnectionRecord.checkout(pool)
  File "D:\Udacity\Azure\cd1756-Azure-Applications-project\env\lib\site-packages\sqlalchemy\pool\base.py", line 492, in checkout
    rec = pool._do_get()
  File "D:\Udacity\Azure\cd1756-Azure-Applications-project\env\lib\site-packages\sqlalchemy\pool\impl.py", line 139, in _do_get
    self._dec_overflow()
  File "D:\Udacity\Azure\cd1756-Azure-Applications-project\env\lib\site-packages\sqlalchemy\util\langhelpers.py", line 68, in __exit__
    compat.reraise(exc_type, exc_value, exc_tb)
  File "D:\Udacity\Azure\cd1756-Azure-Applications-project\env\lib\site-packages\sqlalchemy\util\compat.py", line 153, in reraise
    raise value
  File "D:\Udacity\Azure\cd1756-Azure-Applications-project\env\lib\site-packages\sqlalchemy\pool\impl.py", line 136, in _do_get
    return self._create_connection()
  File "D:\Udacity\Azure\cd1756-Azure-Applications-project\env\lib\site-packages\sqlalchemy\pool\base.py", line 308, in _create_connection
    return _ConnectionRecord(self)
  File "D:\Udacity\Azure\cd1756-Azure-Applications-project\env\lib\site-packages\sqlalchemy\pool\base.py", line 437, in __init__
    self.__connect(first_connect_check=True)
  File "D:\Udacity\Azure\cd1756-Azure-Applications-project\env\lib\site-packages\sqlalchemy\pool\base.py", line 652, in __connect
    connection = pool._invoke_creator(self)
  File "D:\Udacity\Azure\cd1756-Azure-Applications-project\env\lib\site-packages\sqlalchemy\engine\strategies.py", line 114, in connect
    return dialect.connect(*cargs, **cparams)
  File "D:\Udacity\Azure\cd1756-Azure-Applications-project\env\lib\site-packages\sqlalchemy\engine\default.py", line 489, in connect
    return self.dbapi.connect(*cargs, **cparams)
pyodbc.ProgrammingError: ('42000', "[42000] [Microsoft][ODBC Driver 17 for SQL Server][SQL Server]Cannot open server 'article-server' requested by the login. Client with IP address '103.199.33.200' is not allowed to access the server.  To enable access, use the Azure Management Portal or run sp_set_firewall_rule on the master database to create a firewall rule for this IP address or address range.  It may take up to five minutes for this change to take effect. (40615) (SQLDriverConnect); [42000] [Microsoft][ODBC Driver 17 for SQL Server][SQL Server]Cannot open server 'article-server' requested by the login. Client with IP address '103.199.33.200' is not allowed to access the server.  To enable access, use the Azure Management Portal or run sp_set_firewall_rule on the master database to create a firewall rule for this IP address or address range.  It may take up to five minutes for this change to take effect. (40615)")

The above exception was the direct cause of the following exception:

Traceback (most recent call last):
  File "D:\Udacity\Azure\cd1756-Azure-Applications-project\env\lib\site-packages\flask\app.py", line 1982, in wsgi_app
    response = self.full_dispatch_request()
  File "D:\Udacity\Azure\cd1756-Azure-Applications-project\env\lib\site-packages\flask\app.py", line 1614, in full_dispatch_request
    rv = self.handle_user_exception(e)
  File "D:\Udacity\Azure\cd1756-Azure-Applications-project\env\lib\site-packages\flask\app.py", line 1517, in handle_user_exception
    reraise(exc_type, exc_value, tb)
  File "D:\Udacity\Azure\cd1756-Azure-Applications-project\env\lib\site-packages\flask\_compat.py", line 33, in reraise
    raise value
  File "D:\Udacity\Azure\cd1756-Azure-Applications-project\env\lib\site-packages\flask\app.py", line 1612, in full_dispatch_request
    rv = self.dispatch_request()
  File "D:\Udacity\Azure\cd1756-Azure-Applications-project\env\lib\site-packages\flask\app.py", line 1598, in dispatch_request
    return self.view_functions[rule.endpoint](**req.view_args)
  File "D:\Udacity\Azure\cd1756-Azure-Applications-project\env\lib\site-packages\flask_login\utils.py", line 270, in decorated_view
    elif not current_user.is_authenticated:
  File "D:\Udacity\Azure\cd1756-Azure-Applications-project\env\lib\site-packages\werkzeug\local.py", line 348, in __getattr__
    return getattr(self._get_current_object(), name)
  File "D:\Udacity\Azure\cd1756-Azure-Applications-project\env\lib\site-packages\werkzeug\local.py", line 307, in _get_current_object
    return self.__local()
  File "D:\Udacity\Azure\cd1756-Azure-Applications-project\env\lib\site-packages\flask_login\utils.py", line 26, in <lambda>
    current_user = LocalProxy(lambda: _get_user())
  File "D:\Udacity\Azure\cd1756-Azure-Applications-project\env\lib\site-packages\flask_login\utils.py", line 346, in _get_user
    current_app.login_manager._load_user()
  File "D:\Udacity\Azure\cd1756-Azure-Applications-project\env\lib\site-packages\flask_login\login_manager.py", line 318, in _load_user
    user = self._user_callback(user_id)
  File "D:\Udacity\Azure\cd1756-Azure-Applications-project\FlaskWebProject\models.py", line 33, in load_user
    return User.query.get(int(id))
  File "D:\Udacity\Azure\cd1756-Azure-Applications-project\env\lib\site-packages\sqlalchemy\orm\query.py", line 1004, in get
    return self._get_impl(ident, loading.load_on_pk_identity)
  File "D:\Udacity\Azure\cd1756-Azure-Applications-project\env\lib\site-packages\sqlalchemy\orm\query.py", line 1116, in _get_impl
    return db_load_fn(self, primary_key_identity)
  File "D:\Udacity\Azure\cd1756-Azure-Applications-project\env\lib\site-packages\sqlalchemy\orm\loading.py", line 284, in load_on_pk_identity
    return q.one()
  File "D:\Udacity\Azure\cd1756-Azure-Applications-project\env\lib\site-packages\sqlalchemy\orm\query.py", line 3347, in one
    ret = self.one_or_none()
  File "D:\Udacity\Azure\cd1756-Azure-Applications-project\env\lib\site-packages\sqlalchemy\orm\query.py", line 3316, in one_or_none
    ret = list(self)
  File "D:\Udacity\Azure\cd1756-Azure-Applications-project\env\lib\site-packages\sqlalchemy\orm\query.py", line 3389, in __iter__
    return self._execute_and_instances(context)
  File "D:\Udacity\Azure\cd1756-Azure-Applications-project\env\lib\site-packages\sqlalchemy\orm\query.py", line 3411, in _execute_and_instances
    querycontext, self._connection_from_session, close_with_result=True
  File "D:\Udacity\Azure\cd1756-Azure-Applications-project\env\lib\site-packages\sqlalchemy\orm\query.py", line 3426, in _get_bind_args
    mapper=self._bind_mapper(), clause=querycontext.statement, **kw
  File "D:\Udacity\Azure\cd1756-Azure-Applications-project\env\lib\site-packages\sqlalchemy\orm\query.py", line 3404, in _connection_from_session
    conn = self.session.connection(**kw)
  File "D:\Udacity\Azure\cd1756-Azure-Applications-project\env\lib\site-packages\sqlalchemy\orm\session.py", line 1133, in connection
    execution_options=execution_options,
  File "D:\Udacity\Azure\cd1756-Azure-Applications-project\env\lib\site-packages\sqlalchemy\orm\session.py", line 1139, in _connection_for_bind
    engine, execution_options
  File "D:\Udacity\Azure\cd1756-Azure-Applications-project\env\lib\site-packages\sqlalchemy\orm\session.py", line 432, in _connection_for_bind
    conn = bind._contextual_connect()
  File "D:\Udacity\Azure\cd1756-Azure-Applications-project\env\lib\site-packages\sqlalchemy\engine\base.py", line 2242, in _contextual_connect
    self._wrap_pool_connect(self.pool.connect, None),
  File "D:\Udacity\Azure\cd1756-Azure-Applications-project\env\lib\site-packages\sqlalchemy\engine\base.py", line 2280, in _wrap_pool_connect
    e, dialect, self
  File "D:\Udacity\Azure\cd1756-Azure-Applications-project\env\lib\site-packages\sqlalchemy\engine\base.py", line 1547, in _handle_dbapi_exception_noconnection
    util.raise_from_cause(sqlalchemy_exception, exc_info)
  File "D:\Udacity\Azure\cd1756-Azure-Applications-project\env\lib\site-packages\sqlalchemy\util\compat.py", line 398, in raise_from_cause
    reraise(type(exception), exception, tb=exc_tb, cause=cause)
  File "D:\Udacity\Azure\cd1756-Azure-Applications-project\env\lib\site-packages\sqlalchemy\util\compat.py", line 152, in reraise
    raise value.with_traceback(tb)
  File "D:\Udacity\Azure\cd1756-Azure-Applications-project\env\lib\site-packages\sqlalchemy\engine\base.py", line 2276, in _wrap_pool_connect
    return fn()
  File "D:\Udacity\Azure\cd1756-Azure-Applications-project\env\lib\site-packages\sqlalchemy\pool\base.py", line 363, in connect
    return _ConnectionFairy._checkout(self)
  File "D:\Udacity\Azure\cd1756-Azure-Applications-project\env\lib\site-packages\sqlalchemy\pool\base.py", line 773, in _checkout
    fairy = _ConnectionRecord.checkout(pool)
  File "D:\Udacity\Azure\cd1756-Azure-Applications-project\env\lib\site-packages\sqlalchemy\pool\base.py", line 492, in checkout
    rec = pool._do_get()
  File "D:\Udacity\Azure\cd1756-Azure-Applications-project\env\lib\site-packages\sqlalchemy\pool\impl.py", line 139, in _do_get
    self._dec_overflow()
  File "D:\Udacity\Azure\cd1756-Azure-Applications-project\env\lib\site-packages\sqlalchemy\util\langhelpers.py", line 68, in __exit__
    compat.reraise(exc_type, exc_value, exc_tb)
  File "D:\Udacity\Azure\cd1756-Azure-Applications-project\env\lib\site-packages\sqlalchemy\util\compat.py", line 153, in reraise
    raise value
  File "D:\Udacity\Azure\cd1756-Azure-Applications-project\env\lib\site-packages\sqlalchemy\pool\impl.py", line 136, in _do_get
    return self._create_connection()
  File "D:\Udacity\Azure\cd1756-Azure-Applications-project\env\lib\site-packages\sqlalchemy\pool\base.py", line 308, in _create_connection
    return _ConnectionRecord(self)
  File "D:\Udacity\Azure\cd1756-Azure-Applications-project\env\lib\site-packages\sqlalchemy\pool\base.py", line 437, in __init__
    self.__connect(first_connect_check=True)
  File "D:\Udacity\Azure\cd1756-Azure-Applications-project\env\lib\site-packages\sqlalchemy\pool\base.py", line 652, in __connect
    connection = pool._invoke_creator(self)
  File "D:\Udacity\Azure\cd1756-Azure-Applications-project\env\lib\site-packages\sqlalchemy\engine\strategies.py", line 114, in connect
    return dialect.connect(*cargs, **cparams)
  File "D:\Udacity\Azure\cd1756-Azure-Applications-project\env\lib\site-packages\sqlalchemy\engine\default.py", line 489, in connect
    return self.dbapi.connect(*cargs, **cparams)
sqlalchemy.exc.ProgrammingError: (pyodbc.ProgrammingError) ('42000', "[42000] [Microsoft][ODBC Driver 17 for SQL Server][SQL Server]Cannot open server 'article-server' requested by the login. Client with IP address '103.199.33.200' is not allowed to access the server.  To enable access, use the Azure Management Portal or run sp_set_firewall_rule on the master database to create a firewall rule for this IP address or address range.  It may take up to five minutes for this change to take effect. (40615) (SQLDriverConnect); [42000] [Microsoft][ODBC Driver 17 for SQL Server][SQL Server]Cannot open server 'article-server' requested by the login. Client with IP address '103.199.33.200' is not allowed to access the server.  To enable access, use the Azure Management Portal or run sp_set_firewall_rule on the master database to create a firewall rule for this IP address or address range.  It may take up to five minutes for this change to take effect. (40615)")
(Background on this error at: http://sqlalche.me/e/f405)
2023-10-30 16:25:53,411 [ERROR] - Exception on / [GET]
Traceback (most recent call last):
  File "D:\Udacity\Azure\cd1756-Azure-Applications-project\env\lib\site-packages\sqlalchemy\engine\base.py", line 2276, in _wrap_pool_connect
    return fn()
  File "D:\Udacity\Azure\cd1756-Azure-Applications-project\env\lib\site-packages\sqlalchemy\pool\base.py", line 363, in connect
    return _ConnectionFairy._checkout(self)
  File "D:\Udacity\Azure\cd1756-Azure-Applications-project\env\lib\site-packages\sqlalchemy\pool\base.py", line 773, in _checkout
    fairy = _ConnectionRecord.checkout(pool)
  File "D:\Udacity\Azure\cd1756-Azure-Applications-project\env\lib\site-packages\sqlalchemy\pool\base.py", line 492, in checkout
    rec = pool._do_get()
  File "D:\Udacity\Azure\cd1756-Azure-Applications-project\env\lib\site-packages\sqlalchemy\pool\impl.py", line 139, in _do_get
    self._dec_overflow()
  File "D:\Udacity\Azure\cd1756-Azure-Applications-project\env\lib\site-packages\sqlalchemy\util\langhelpers.py", line 68, in __exit__
    compat.reraise(exc_type, exc_value, exc_tb)
  File "D:\Udacity\Azure\cd1756-Azure-Applications-project\env\lib\site-packages\sqlalchemy\util\compat.py", line 153, in reraise
    raise value
  File "D:\Udacity\Azure\cd1756-Azure-Applications-project\env\lib\site-packages\sqlalchemy\pool\impl.py", line 136, in _do_get
    return self._create_connection()
  File "D:\Udacity\Azure\cd1756-Azure-Applications-project\env\lib\site-packages\sqlalchemy\pool\base.py", line 308, in _create_connection
    return _ConnectionRecord(self)
  File "D:\Udacity\Azure\cd1756-Azure-Applications-project\env\lib\site-packages\sqlalchemy\pool\base.py", line 437, in __init__
    self.__connect(first_connect_check=True)
  File "D:\Udacity\Azure\cd1756-Azure-Applications-project\env\lib\site-packages\sqlalchemy\pool\base.py", line 652, in __connect
    connection = pool._invoke_creator(self)
  File "D:\Udacity\Azure\cd1756-Azure-Applications-project\env\lib\site-packages\sqlalchemy\engine\strategies.py", line 114, in connect
    return dialect.connect(*cargs, **cparams)
  File "D:\Udacity\Azure\cd1756-Azure-Applications-project\env\lib\site-packages\sqlalchemy\engine\default.py", line 489, in connect
    return self.dbapi.connect(*cargs, **cparams)
pyodbc.ProgrammingError: ('42000', "[42000] [Microsoft][ODBC Driver 17 for SQL Server][SQL Server]Cannot open server 'article-server' requested by the login. Client with IP address '103.199.33.200' is not allowed to access the server.  To enable access, use the Azure Management Portal or run sp_set_firewall_rule on the master database to create a firewall rule for this IP address or address range.  It may take up to five minutes for this change to take effect. (40615) (SQLDriverConnect); [42000] [Microsoft][ODBC Driver 17 for SQL Server][SQL Server]Cannot open server 'article-server' requested by the login. Client with IP address '103.199.33.200' is not allowed to access the server.  To enable access, use the Azure Management Portal or run sp_set_firewall_rule on the master database to create a firewall rule for this IP address or address range.  It may take up to five minutes for this change to take effect. (40615)")

The above exception was the direct cause of the following exception:

Traceback (most recent call last):
  File "D:\Udacity\Azure\cd1756-Azure-Applications-project\env\lib\site-packages\flask\app.py", line 1982, in wsgi_app
    response = self.full_dispatch_request()
  File "D:\Udacity\Azure\cd1756-Azure-Applications-project\env\lib\site-packages\flask\app.py", line 1614, in full_dispatch_request
    rv = self.handle_user_exception(e)
  File "D:\Udacity\Azure\cd1756-Azure-Applications-project\env\lib\site-packages\flask\app.py", line 1517, in handle_user_exception
    reraise(exc_type, exc_value, tb)
  File "D:\Udacity\Azure\cd1756-Azure-Applications-project\env\lib\site-packages\flask\_compat.py", line 33, in reraise
    raise value
  File "D:\Udacity\Azure\cd1756-Azure-Applications-project\env\lib\site-packages\flask\app.py", line 1612, in full_dispatch_request
    rv = self.dispatch_request()
  File "D:\Udacity\Azure\cd1756-Azure-Applications-project\env\lib\site-packages\flask\app.py", line 1598, in dispatch_request
    return self.view_functions[rule.endpoint](**req.view_args)
  File "D:\Udacity\Azure\cd1756-Azure-Applications-project\env\lib\site-packages\flask_login\utils.py", line 270, in decorated_view
    elif not current_user.is_authenticated:
  File "D:\Udacity\Azure\cd1756-Azure-Applications-project\env\lib\site-packages\werkzeug\local.py", line 348, in __getattr__
    return getattr(self._get_current_object(), name)
  File "D:\Udacity\Azure\cd1756-Azure-Applications-project\env\lib\site-packages\werkzeug\local.py", line 307, in _get_current_object
    return self.__local()
  File "D:\Udacity\Azure\cd1756-Azure-Applications-project\env\lib\site-packages\flask_login\utils.py", line 26, in <lambda>
    current_user = LocalProxy(lambda: _get_user())
  File "D:\Udacity\Azure\cd1756-Azure-Applications-project\env\lib\site-packages\flask_login\utils.py", line 346, in _get_user
    current_app.login_manager._load_user()
  File "D:\Udacity\Azure\cd1756-Azure-Applications-project\env\lib\site-packages\flask_login\login_manager.py", line 318, in _load_user
    user = self._user_callback(user_id)
  File "D:\Udacity\Azure\cd1756-Azure-Applications-project\FlaskWebProject\models.py", line 33, in load_user
    return User.query.get(int(id))
  File "D:\Udacity\Azure\cd1756-Azure-Applications-project\env\lib\site-packages\sqlalchemy\orm\query.py", line 1004, in get
    return self._get_impl(ident, loading.load_on_pk_identity)
  File "D:\Udacity\Azure\cd1756-Azure-Applications-project\env\lib\site-packages\sqlalchemy\orm\query.py", line 1116, in _get_impl
    return db_load_fn(self, primary_key_identity)
  File "D:\Udacity\Azure\cd1756-Azure-Applications-project\env\lib\site-packages\sqlalchemy\orm\loading.py", line 284, in load_on_pk_identity
    return q.one()
  File "D:\Udacity\Azure\cd1756-Azure-Applications-project\env\lib\site-packages\sqlalchemy\orm\query.py", line 3347, in one
    ret = self.one_or_none()
  File "D:\Udacity\Azure\cd1756-Azure-Applications-project\env\lib\site-packages\sqlalchemy\orm\query.py", line 3316, in one_or_none
    ret = list(self)
  File "D:\Udacity\Azure\cd1756-Azure-Applications-project\env\lib\site-packages\sqlalchemy\orm\query.py", line 3389, in __iter__
    return self._execute_and_instances(context)
  File "D:\Udacity\Azure\cd1756-Azure-Applications-project\env\lib\site-packages\sqlalchemy\orm\query.py", line 3411, in _execute_and_instances
    querycontext, self._connection_from_session, close_with_result=True
  File "D:\Udacity\Azure\cd1756-Azure-Applications-project\env\lib\site-packages\sqlalchemy\orm\query.py", line 3426, in _get_bind_args
    mapper=self._bind_mapper(), clause=querycontext.statement, **kw
  File "D:\Udacity\Azure\cd1756-Azure-Applications-project\env\lib\site-packages\sqlalchemy\orm\query.py", line 3404, in _connection_from_session
    conn = self.session.connection(**kw)
  File "D:\Udacity\Azure\cd1756-Azure-Applications-project\env\lib\site-packages\sqlalchemy\orm\session.py", line 1133, in connection
    execution_options=execution_options,
  File "D:\Udacity\Azure\cd1756-Azure-Applications-project\env\lib\site-packages\sqlalchemy\orm\session.py", line 1139, in _connection_for_bind
    engine, execution_options
  File "D:\Udacity\Azure\cd1756-Azure-Applications-project\env\lib\site-packages\sqlalchemy\orm\session.py", line 432, in _connection_for_bind
    conn = bind._contextual_connect()
  File "D:\Udacity\Azure\cd1756-Azure-Applications-project\env\lib\site-packages\sqlalchemy\engine\base.py", line 2242, in _contextual_connect
    self._wrap_pool_connect(self.pool.connect, None),
  File "D:\Udacity\Azure\cd1756-Azure-Applications-project\env\lib\site-packages\sqlalchemy\engine\base.py", line 2280, in _wrap_pool_connect
    e, dialect, self
  File "D:\Udacity\Azure\cd1756-Azure-Applications-project\env\lib\site-packages\sqlalchemy\engine\base.py", line 1547, in _handle_dbapi_exception_noconnection
    util.raise_from_cause(sqlalchemy_exception, exc_info)
  File "D:\Udacity\Azure\cd1756-Azure-Applications-project\env\lib\site-packages\sqlalchemy\util\compat.py", line 398, in raise_from_cause
    reraise(type(exception), exception, tb=exc_tb, cause=cause)
  File "D:\Udacity\Azure\cd1756-Azure-Applications-project\env\lib\site-packages\sqlalchemy\util\compat.py", line 152, in reraise
    raise value.with_traceback(tb)
  File "D:\Udacity\Azure\cd1756-Azure-Applications-project\env\lib\site-packages\sqlalchemy\engine\base.py", line 2276, in _wrap_pool_connect
    return fn()
  File "D:\Udacity\Azure\cd1756-Azure-Applications-project\env\lib\site-packages\sqlalchemy\pool\base.py", line 363, in connect
    return _ConnectionFairy._checkout(self)
  File "D:\Udacity\Azure\cd1756-Azure-Applications-project\env\lib\site-packages\sqlalchemy\pool\base.py", line 773, in _checkout
    fairy = _ConnectionRecord.checkout(pool)
  File "D:\Udacity\Azure\cd1756-Azure-Applications-project\env\lib\site-packages\sqlalchemy\pool\base.py", line 492, in checkout
    rec = pool._do_get()
  File "D:\Udacity\Azure\cd1756-Azure-Applications-project\env\lib\site-packages\sqlalchemy\pool\impl.py", line 139, in _do_get
    self._dec_overflow()
  File "D:\Udacity\Azure\cd1756-Azure-Applications-project\env\lib\site-packages\sqlalchemy\util\langhelpers.py", line 68, in __exit__
    compat.reraise(exc_type, exc_value, exc_tb)
  File "D:\Udacity\Azure\cd1756-Azure-Applications-project\env\lib\site-packages\sqlalchemy\util\compat.py", line 153, in reraise
    raise value
  File "D:\Udacity\Azure\cd1756-Azure-Applications-project\env\lib\site-packages\sqlalchemy\pool\impl.py", line 136, in _do_get
    return self._create_connection()
  File "D:\Udacity\Azure\cd1756-Azure-Applications-project\env\lib\site-packages\sqlalchemy\pool\base.py", line 308, in _create_connection
    return _ConnectionRecord(self)
  File "D:\Udacity\Azure\cd1756-Azure-Applications-project\env\lib\site-packages\sqlalchemy\pool\base.py", line 437, in __init__
    self.__connect(first_connect_check=True)
  File "D:\Udacity\Azure\cd1756-Azure-Applications-project\env\lib\site-packages\sqlalchemy\pool\base.py", line 652, in __connect
    connection = pool._invoke_creator(self)
  File "D:\Udacity\Azure\cd1756-Azure-Applications-project\env\lib\site-packages\sqlalchemy\engine\strategies.py", line 114, in connect
    return dialect.connect(*cargs, **cparams)
  File "D:\Udacity\Azure\cd1756-Azure-Applications-project\env\lib\site-packages\sqlalchemy\engine\default.py", line 489, in connect
    return self.dbapi.connect(*cargs, **cparams)
sqlalchemy.exc.ProgrammingError: (pyodbc.ProgrammingError) ('42000', "[42000] [Microsoft][ODBC Driver 17 for SQL Server][SQL Server]Cannot open server 'article-server' requested by the login. Client with IP address '103.199.33.200' is not allowed to access the server.  To enable access, use the Azure Management Portal or run sp_set_firewall_rule on the master database to create a firewall rule for this IP address or address range.  It may take up to five minutes for this change to take effect. (40615) (SQLDriverConnect); [42000] [Microsoft][ODBC Driver 17 for SQL Server][SQL Server]Cannot open server 'article-server' requested by the login. Client with IP address '103.199.33.200' is not allowed to access the server.  To enable access, use the Azure Management Portal or run sp_set_firewall_rule on the master database to create a firewall rule for this IP address or address range.  It may take up to five minutes for this change to take effect. (40615)")
(Background on this error at: http://sqlalche.me/e/f405)
2023-10-30 16:27:03,547 [ERROR] - Exception on / [GET]
Traceback (most recent call last):
  File "D:\Udacity\Azure\cd1756-Azure-Applications-project\env\lib\site-packages\sqlalchemy\engine\base.py", line 2276, in _wrap_pool_connect
    return fn()
  File "D:\Udacity\Azure\cd1756-Azure-Applications-project\env\lib\site-packages\sqlalchemy\pool\base.py", line 363, in connect
    return _ConnectionFairy._checkout(self)
  File "D:\Udacity\Azure\cd1756-Azure-Applications-project\env\lib\site-packages\sqlalchemy\pool\base.py", line 773, in _checkout
    fairy = _ConnectionRecord.checkout(pool)
  File "D:\Udacity\Azure\cd1756-Azure-Applications-project\env\lib\site-packages\sqlalchemy\pool\base.py", line 492, in checkout
    rec = pool._do_get()
  File "D:\Udacity\Azure\cd1756-Azure-Applications-project\env\lib\site-packages\sqlalchemy\pool\impl.py", line 139, in _do_get
    self._dec_overflow()
  File "D:\Udacity\Azure\cd1756-Azure-Applications-project\env\lib\site-packages\sqlalchemy\util\langhelpers.py", line 68, in __exit__
    compat.reraise(exc_type, exc_value, exc_tb)
  File "D:\Udacity\Azure\cd1756-Azure-Applications-project\env\lib\site-packages\sqlalchemy\util\compat.py", line 153, in reraise
    raise value
  File "D:\Udacity\Azure\cd1756-Azure-Applications-project\env\lib\site-packages\sqlalchemy\pool\impl.py", line 136, in _do_get
    return self._create_connection()
  File "D:\Udacity\Azure\cd1756-Azure-Applications-project\env\lib\site-packages\sqlalchemy\pool\base.py", line 308, in _create_connection
    return _ConnectionRecord(self)
  File "D:\Udacity\Azure\cd1756-Azure-Applications-project\env\lib\site-packages\sqlalchemy\pool\base.py", line 437, in __init__
    self.__connect(first_connect_check=True)
  File "D:\Udacity\Azure\cd1756-Azure-Applications-project\env\lib\site-packages\sqlalchemy\pool\base.py", line 652, in __connect
    connection = pool._invoke_creator(self)
  File "D:\Udacity\Azure\cd1756-Azure-Applications-project\env\lib\site-packages\sqlalchemy\engine\strategies.py", line 114, in connect
    return dialect.connect(*cargs, **cparams)
  File "D:\Udacity\Azure\cd1756-Azure-Applications-project\env\lib\site-packages\sqlalchemy\engine\default.py", line 489, in connect
    return self.dbapi.connect(*cargs, **cparams)
pyodbc.ProgrammingError: ('42000', "[42000] [Microsoft][ODBC Driver 17 for SQL Server][SQL Server]Cannot open server 'article-server' requested by the login. Client with IP address '103.199.33.200' is not allowed to access the server.  To enable access, use the Azure Management Portal or run sp_set_firewall_rule on the master database to create a firewall rule for this IP address or address range.  It may take up to five minutes for this change to take effect. (40615) (SQLDriverConnect); [42000] [Microsoft][ODBC Driver 17 for SQL Server][SQL Server]Cannot open server 'article-server' requested by the login. Client with IP address '103.199.33.200' is not allowed to access the server.  To enable access, use the Azure Management Portal or run sp_set_firewall_rule on the master database to create a firewall rule for this IP address or address range.  It may take up to five minutes for this change to take effect. (40615)")

The above exception was the direct cause of the following exception:

Traceback (most recent call last):
  File "D:\Udacity\Azure\cd1756-Azure-Applications-project\env\lib\site-packages\flask\app.py", line 1982, in wsgi_app
    response = self.full_dispatch_request()
  File "D:\Udacity\Azure\cd1756-Azure-Applications-project\env\lib\site-packages\flask\app.py", line 1614, in full_dispatch_request
    rv = self.handle_user_exception(e)
  File "D:\Udacity\Azure\cd1756-Azure-Applications-project\env\lib\site-packages\flask\app.py", line 1517, in handle_user_exception
    reraise(exc_type, exc_value, tb)
  File "D:\Udacity\Azure\cd1756-Azure-Applications-project\env\lib\site-packages\flask\_compat.py", line 33, in reraise
    raise value
  File "D:\Udacity\Azure\cd1756-Azure-Applications-project\env\lib\site-packages\flask\app.py", line 1612, in full_dispatch_request
    rv = self.dispatch_request()
  File "D:\Udacity\Azure\cd1756-Azure-Applications-project\env\lib\site-packages\flask\app.py", line 1598, in dispatch_request
    return self.view_functions[rule.endpoint](**req.view_args)
  File "D:\Udacity\Azure\cd1756-Azure-Applications-project\env\lib\site-packages\flask_login\utils.py", line 270, in decorated_view
    elif not current_user.is_authenticated:
  File "D:\Udacity\Azure\cd1756-Azure-Applications-project\env\lib\site-packages\werkzeug\local.py", line 348, in __getattr__
    return getattr(self._get_current_object(), name)
  File "D:\Udacity\Azure\cd1756-Azure-Applications-project\env\lib\site-packages\werkzeug\local.py", line 307, in _get_current_object
    return self.__local()
  File "D:\Udacity\Azure\cd1756-Azure-Applications-project\env\lib\site-packages\flask_login\utils.py", line 26, in <lambda>
    current_user = LocalProxy(lambda: _get_user())
  File "D:\Udacity\Azure\cd1756-Azure-Applications-project\env\lib\site-packages\flask_login\utils.py", line 346, in _get_user
    current_app.login_manager._load_user()
  File "D:\Udacity\Azure\cd1756-Azure-Applications-project\env\lib\site-packages\flask_login\login_manager.py", line 318, in _load_user
    user = self._user_callback(user_id)
  File "D:\Udacity\Azure\cd1756-Azure-Applications-project\FlaskWebProject\models.py", line 33, in load_user
    return User.query.get(int(id))
  File "D:\Udacity\Azure\cd1756-Azure-Applications-project\env\lib\site-packages\sqlalchemy\orm\query.py", line 1004, in get
    return self._get_impl(ident, loading.load_on_pk_identity)
  File "D:\Udacity\Azure\cd1756-Azure-Applications-project\env\lib\site-packages\sqlalchemy\orm\query.py", line 1116, in _get_impl
    return db_load_fn(self, primary_key_identity)
  File "D:\Udacity\Azure\cd1756-Azure-Applications-project\env\lib\site-packages\sqlalchemy\orm\loading.py", line 284, in load_on_pk_identity
    return q.one()
  File "D:\Udacity\Azure\cd1756-Azure-Applications-project\env\lib\site-packages\sqlalchemy\orm\query.py", line 3347, in one
    ret = self.one_or_none()
  File "D:\Udacity\Azure\cd1756-Azure-Applications-project\env\lib\site-packages\sqlalchemy\orm\query.py", line 3316, in one_or_none
    ret = list(self)
  File "D:\Udacity\Azure\cd1756-Azure-Applications-project\env\lib\site-packages\sqlalchemy\orm\query.py", line 3389, in __iter__
    return self._execute_and_instances(context)
  File "D:\Udacity\Azure\cd1756-Azure-Applications-project\env\lib\site-packages\sqlalchemy\orm\query.py", line 3411, in _execute_and_instances
    querycontext, self._connection_from_session, close_with_result=True
  File "D:\Udacity\Azure\cd1756-Azure-Applications-project\env\lib\site-packages\sqlalchemy\orm\query.py", line 3426, in _get_bind_args
    mapper=self._bind_mapper(), clause=querycontext.statement, **kw
  File "D:\Udacity\Azure\cd1756-Azure-Applications-project\env\lib\site-packages\sqlalchemy\orm\query.py", line 3404, in _connection_from_session
    conn = self.session.connection(**kw)
  File "D:\Udacity\Azure\cd1756-Azure-Applications-project\env\lib\site-packages\sqlalchemy\orm\session.py", line 1133, in connection
    execution_options=execution_options,
  File "D:\Udacity\Azure\cd1756-Azure-Applications-project\env\lib\site-packages\sqlalchemy\orm\session.py", line 1139, in _connection_for_bind
    engine, execution_options
  File "D:\Udacity\Azure\cd1756-Azure-Applications-project\env\lib\site-packages\sqlalchemy\orm\session.py", line 432, in _connection_for_bind
    conn = bind._contextual_connect()
  File "D:\Udacity\Azure\cd1756-Azure-Applications-project\env\lib\site-packages\sqlalchemy\engine\base.py", line 2242, in _contextual_connect
    self._wrap_pool_connect(self.pool.connect, None),
  File "D:\Udacity\Azure\cd1756-Azure-Applications-project\env\lib\site-packages\sqlalchemy\engine\base.py", line 2280, in _wrap_pool_connect
    e, dialect, self
  File "D:\Udacity\Azure\cd1756-Azure-Applications-project\env\lib\site-packages\sqlalchemy\engine\base.py", line 1547, in _handle_dbapi_exception_noconnection
    util.raise_from_cause(sqlalchemy_exception, exc_info)
  File "D:\Udacity\Azure\cd1756-Azure-Applications-project\env\lib\site-packages\sqlalchemy\util\compat.py", line 398, in raise_from_cause
    reraise(type(exception), exception, tb=exc_tb, cause=cause)
  File "D:\Udacity\Azure\cd1756-Azure-Applications-project\env\lib\site-packages\sqlalchemy\util\compat.py", line 152, in reraise
    raise value.with_traceback(tb)
  File "D:\Udacity\Azure\cd1756-Azure-Applications-project\env\lib\site-packages\sqlalchemy\engine\base.py", line 2276, in _wrap_pool_connect
    return fn()
  File "D:\Udacity\Azure\cd1756-Azure-Applications-project\env\lib\site-packages\sqlalchemy\pool\base.py", line 363, in connect
    return _ConnectionFairy._checkout(self)
  File "D:\Udacity\Azure\cd1756-Azure-Applications-project\env\lib\site-packages\sqlalchemy\pool\base.py", line 773, in _checkout
    fairy = _ConnectionRecord.checkout(pool)
  File "D:\Udacity\Azure\cd1756-Azure-Applications-project\env\lib\site-packages\sqlalchemy\pool\base.py", line 492, in checkout
    rec = pool._do_get()
  File "D:\Udacity\Azure\cd1756-Azure-Applications-project\env\lib\site-packages\sqlalchemy\pool\impl.py", line 139, in _do_get
    self._dec_overflow()
  File "D:\Udacity\Azure\cd1756-Azure-Applications-project\env\lib\site-packages\sqlalchemy\util\langhelpers.py", line 68, in __exit__
    compat.reraise(exc_type, exc_value, exc_tb)
  File "D:\Udacity\Azure\cd1756-Azure-Applications-project\env\lib\site-packages\sqlalchemy\util\compat.py", line 153, in reraise
    raise value
  File "D:\Udacity\Azure\cd1756-Azure-Applications-project\env\lib\site-packages\sqlalchemy\pool\impl.py", line 136, in _do_get
    return self._create_connection()
  File "D:\Udacity\Azure\cd1756-Azure-Applications-project\env\lib\site-packages\sqlalchemy\pool\base.py", line 308, in _create_connection
    return _ConnectionRecord(self)
  File "D:\Udacity\Azure\cd1756-Azure-Applications-project\env\lib\site-packages\sqlalchemy\pool\base.py", line 437, in __init__
    self.__connect(first_connect_check=True)
  File "D:\Udacity\Azure\cd1756-Azure-Applications-project\env\lib\site-packages\sqlalchemy\pool\base.py", line 652, in __connect
    connection = pool._invoke_creator(self)
  File "D:\Udacity\Azure\cd1756-Azure-Applications-project\env\lib\site-packages\sqlalchemy\engine\strategies.py", line 114, in connect
    return dialect.connect(*cargs, **cparams)
  File "D:\Udacity\Azure\cd1756-Azure-Applications-project\env\lib\site-packages\sqlalchemy\engine\default.py", line 489, in connect
    return self.dbapi.connect(*cargs, **cparams)
sqlalchemy.exc.ProgrammingError: (pyodbc.ProgrammingError) ('42000', "[42000] [Microsoft][ODBC Driver 17 for SQL Server][SQL Server]Cannot open server 'article-server' requested by the login. Client with IP address '103.199.33.200' is not allowed to access the server.  To enable access, use the Azure Management Portal or run sp_set_firewall_rule on the master database to create a firewall rule for this IP address or address range.  It may take up to five minutes for this change to take effect. (40615) (SQLDriverConnect); [42000] [Microsoft][ODBC Driver 17 for SQL Server][SQL Server]Cannot open server 'article-server' requested by the login. Client with IP address '103.199.33.200' is not allowed to access the server.  To enable access, use the Azure Management Portal or run sp_set_firewall_rule on the master database to create a firewall rule for this IP address or address range.  It may take up to five minutes for this change to take effect. (40615)")
(Background on this error at: http://sqlalche.me/e/f405)
2023-10-30 16:28:39,582 [ERROR] - Exception on / [GET]
Traceback (most recent call last):
  File "D:\Udacity\Azure\cd1756-Azure-Applications-project\env\lib\site-packages\sqlalchemy\engine\base.py", line 2276, in _wrap_pool_connect
    return fn()
  File "D:\Udacity\Azure\cd1756-Azure-Applications-project\env\lib\site-packages\sqlalchemy\pool\base.py", line 363, in connect
    return _ConnectionFairy._checkout(self)
  File "D:\Udacity\Azure\cd1756-Azure-Applications-project\env\lib\site-packages\sqlalchemy\pool\base.py", line 773, in _checkout
    fairy = _ConnectionRecord.checkout(pool)
  File "D:\Udacity\Azure\cd1756-Azure-Applications-project\env\lib\site-packages\sqlalchemy\pool\base.py", line 492, in checkout
    rec = pool._do_get()
  File "D:\Udacity\Azure\cd1756-Azure-Applications-project\env\lib\site-packages\sqlalchemy\pool\impl.py", line 139, in _do_get
    self._dec_overflow()
  File "D:\Udacity\Azure\cd1756-Azure-Applications-project\env\lib\site-packages\sqlalchemy\util\langhelpers.py", line 68, in __exit__
    compat.reraise(exc_type, exc_value, exc_tb)
  File "D:\Udacity\Azure\cd1756-Azure-Applications-project\env\lib\site-packages\sqlalchemy\util\compat.py", line 153, in reraise
    raise value
  File "D:\Udacity\Azure\cd1756-Azure-Applications-project\env\lib\site-packages\sqlalchemy\pool\impl.py", line 136, in _do_get
    return self._create_connection()
  File "D:\Udacity\Azure\cd1756-Azure-Applications-project\env\lib\site-packages\sqlalchemy\pool\base.py", line 308, in _create_connection
    return _ConnectionRecord(self)
  File "D:\Udacity\Azure\cd1756-Azure-Applications-project\env\lib\site-packages\sqlalchemy\pool\base.py", line 437, in __init__
    self.__connect(first_connect_check=True)
  File "D:\Udacity\Azure\cd1756-Azure-Applications-project\env\lib\site-packages\sqlalchemy\pool\base.py", line 652, in __connect
    connection = pool._invoke_creator(self)
  File "D:\Udacity\Azure\cd1756-Azure-Applications-project\env\lib\site-packages\sqlalchemy\engine\strategies.py", line 114, in connect
    return dialect.connect(*cargs, **cparams)
  File "D:\Udacity\Azure\cd1756-Azure-Applications-project\env\lib\site-packages\sqlalchemy\engine\default.py", line 489, in connect
    return self.dbapi.connect(*cargs, **cparams)
pyodbc.ProgrammingError: ('42000', "[42000] [Microsoft][ODBC Driver 17 for SQL Server][SQL Server]Cannot open server 'article-server' requested by the login. Client with IP address '103.199.33.200' is not allowed to access the server.  To enable access, use the Azure Management Portal or run sp_set_firewall_rule on the master database to create a firewall rule for this IP address or address range.  It may take up to five minutes for this change to take effect. (40615) (SQLDriverConnect); [42000] [Microsoft][ODBC Driver 17 for SQL Server][SQL Server]Cannot open server 'article-server' requested by the login. Client with IP address '103.199.33.200' is not allowed to access the server.  To enable access, use the Azure Management Portal or run sp_set_firewall_rule on the master database to create a firewall rule for this IP address or address range.  It may take up to five minutes for this change to take effect. (40615)")

The above exception was the direct cause of the following exception:

Traceback (most recent call last):
  File "D:\Udacity\Azure\cd1756-Azure-Applications-project\env\lib\site-packages\flask\app.py", line 1982, in wsgi_app
    response = self.full_dispatch_request()
  File "D:\Udacity\Azure\cd1756-Azure-Applications-project\env\lib\site-packages\flask\app.py", line 1614, in full_dispatch_request
    rv = self.handle_user_exception(e)
  File "D:\Udacity\Azure\cd1756-Azure-Applications-project\env\lib\site-packages\flask\app.py", line 1517, in handle_user_exception
    reraise(exc_type, exc_value, tb)
  File "D:\Udacity\Azure\cd1756-Azure-Applications-project\env\lib\site-packages\flask\_compat.py", line 33, in reraise
    raise value
  File "D:\Udacity\Azure\cd1756-Azure-Applications-project\env\lib\site-packages\flask\app.py", line 1612, in full_dispatch_request
    rv = self.dispatch_request()
  File "D:\Udacity\Azure\cd1756-Azure-Applications-project\env\lib\site-packages\flask\app.py", line 1598, in dispatch_request
    return self.view_functions[rule.endpoint](**req.view_args)
  File "D:\Udacity\Azure\cd1756-Azure-Applications-project\env\lib\site-packages\flask_login\utils.py", line 270, in decorated_view
    elif not current_user.is_authenticated:
  File "D:\Udacity\Azure\cd1756-Azure-Applications-project\env\lib\site-packages\werkzeug\local.py", line 348, in __getattr__
    return getattr(self._get_current_object(), name)
  File "D:\Udacity\Azure\cd1756-Azure-Applications-project\env\lib\site-packages\werkzeug\local.py", line 307, in _get_current_object
    return self.__local()
  File "D:\Udacity\Azure\cd1756-Azure-Applications-project\env\lib\site-packages\flask_login\utils.py", line 26, in <lambda>
    current_user = LocalProxy(lambda: _get_user())
  File "D:\Udacity\Azure\cd1756-Azure-Applications-project\env\lib\site-packages\flask_login\utils.py", line 346, in _get_user
    current_app.login_manager._load_user()
  File "D:\Udacity\Azure\cd1756-Azure-Applications-project\env\lib\site-packages\flask_login\login_manager.py", line 318, in _load_user
    user = self._user_callback(user_id)
  File "D:\Udacity\Azure\cd1756-Azure-Applications-project\FlaskWebProject\models.py", line 33, in load_user
    return User.query.get(int(id))
  File "D:\Udacity\Azure\cd1756-Azure-Applications-project\env\lib\site-packages\sqlalchemy\orm\query.py", line 1004, in get
    return self._get_impl(ident, loading.load_on_pk_identity)
  File "D:\Udacity\Azure\cd1756-Azure-Applications-project\env\lib\site-packages\sqlalchemy\orm\query.py", line 1116, in _get_impl
    return db_load_fn(self, primary_key_identity)
  File "D:\Udacity\Azure\cd1756-Azure-Applications-project\env\lib\site-packages\sqlalchemy\orm\loading.py", line 284, in load_on_pk_identity
    return q.one()
  File "D:\Udacity\Azure\cd1756-Azure-Applications-project\env\lib\site-packages\sqlalchemy\orm\query.py", line 3347, in one
    ret = self.one_or_none()
  File "D:\Udacity\Azure\cd1756-Azure-Applications-project\env\lib\site-packages\sqlalchemy\orm\query.py", line 3316, in one_or_none
    ret = list(self)
  File "D:\Udacity\Azure\cd1756-Azure-Applications-project\env\lib\site-packages\sqlalchemy\orm\query.py", line 3389, in __iter__
    return self._execute_and_instances(context)
  File "D:\Udacity\Azure\cd1756-Azure-Applications-project\env\lib\site-packages\sqlalchemy\orm\query.py", line 3411, in _execute_and_instances
    querycontext, self._connection_from_session, close_with_result=True
  File "D:\Udacity\Azure\cd1756-Azure-Applications-project\env\lib\site-packages\sqlalchemy\orm\query.py", line 3426, in _get_bind_args
    mapper=self._bind_mapper(), clause=querycontext.statement, **kw
  File "D:\Udacity\Azure\cd1756-Azure-Applications-project\env\lib\site-packages\sqlalchemy\orm\query.py", line 3404, in _connection_from_session
    conn = self.session.connection(**kw)
  File "D:\Udacity\Azure\cd1756-Azure-Applications-project\env\lib\site-packages\sqlalchemy\orm\session.py", line 1133, in connection
    execution_options=execution_options,
  File "D:\Udacity\Azure\cd1756-Azure-Applications-project\env\lib\site-packages\sqlalchemy\orm\session.py", line 1139, in _connection_for_bind
    engine, execution_options
  File "D:\Udacity\Azure\cd1756-Azure-Applications-project\env\lib\site-packages\sqlalchemy\orm\session.py", line 432, in _connection_for_bind
    conn = bind._contextual_connect()
  File "D:\Udacity\Azure\cd1756-Azure-Applications-project\env\lib\site-packages\sqlalchemy\engine\base.py", line 2242, in _contextual_connect
    self._wrap_pool_connect(self.pool.connect, None),
  File "D:\Udacity\Azure\cd1756-Azure-Applications-project\env\lib\site-packages\sqlalchemy\engine\base.py", line 2280, in _wrap_pool_connect
    e, dialect, self
  File "D:\Udacity\Azure\cd1756-Azure-Applications-project\env\lib\site-packages\sqlalchemy\engine\base.py", line 1547, in _handle_dbapi_exception_noconnection
    util.raise_from_cause(sqlalchemy_exception, exc_info)
  File "D:\Udacity\Azure\cd1756-Azure-Applications-project\env\lib\site-packages\sqlalchemy\util\compat.py", line 398, in raise_from_cause
    reraise(type(exception), exception, tb=exc_tb, cause=cause)
  File "D:\Udacity\Azure\cd1756-Azure-Applications-project\env\lib\site-packages\sqlalchemy\util\compat.py", line 152, in reraise
    raise value.with_traceback(tb)
  File "D:\Udacity\Azure\cd1756-Azure-Applications-project\env\lib\site-packages\sqlalchemy\engine\base.py", line 2276, in _wrap_pool_connect
    return fn()
  File "D:\Udacity\Azure\cd1756-Azure-Applications-project\env\lib\site-packages\sqlalchemy\pool\base.py", line 363, in connect
    return _ConnectionFairy._checkout(self)
  File "D:\Udacity\Azure\cd1756-Azure-Applications-project\env\lib\site-packages\sqlalchemy\pool\base.py", line 773, in _checkout
    fairy = _ConnectionRecord.checkout(pool)
  File "D:\Udacity\Azure\cd1756-Azure-Applications-project\env\lib\site-packages\sqlalchemy\pool\base.py", line 492, in checkout
    rec = pool._do_get()
  File "D:\Udacity\Azure\cd1756-Azure-Applications-project\env\lib\site-packages\sqlalchemy\pool\impl.py", line 139, in _do_get
    self._dec_overflow()
  File "D:\Udacity\Azure\cd1756-Azure-Applications-project\env\lib\site-packages\sqlalchemy\util\langhelpers.py", line 68, in __exit__
    compat.reraise(exc_type, exc_value, exc_tb)
  File "D:\Udacity\Azure\cd1756-Azure-Applications-project\env\lib\site-packages\sqlalchemy\util\compat.py", line 153, in reraise
    raise value
  File "D:\Udacity\Azure\cd1756-Azure-Applications-project\env\lib\site-packages\sqlalchemy\pool\impl.py", line 136, in _do_get
    return self._create_connection()
  File "D:\Udacity\Azure\cd1756-Azure-Applications-project\env\lib\site-packages\sqlalchemy\pool\base.py", line 308, in _create_connection
    return _ConnectionRecord(self)
  File "D:\Udacity\Azure\cd1756-Azure-Applications-project\env\lib\site-packages\sqlalchemy\pool\base.py", line 437, in __init__
    self.__connect(first_connect_check=True)
  File "D:\Udacity\Azure\cd1756-Azure-Applications-project\env\lib\site-packages\sqlalchemy\pool\base.py", line 652, in __connect
    connection = pool._invoke_creator(self)
  File "D:\Udacity\Azure\cd1756-Azure-Applications-project\env\lib\site-packages\sqlalchemy\engine\strategies.py", line 114, in connect
    return dialect.connect(*cargs, **cparams)
  File "D:\Udacity\Azure\cd1756-Azure-Applications-project\env\lib\site-packages\sqlalchemy\engine\default.py", line 489, in connect
    return self.dbapi.connect(*cargs, **cparams)
sqlalchemy.exc.ProgrammingError: (pyodbc.ProgrammingError) ('42000', "[42000] [Microsoft][ODBC Driver 17 for SQL Server][SQL Server]Cannot open server 'article-server' requested by the login. Client with IP address '103.199.33.200' is not allowed to access the server.  To enable access, use the Azure Management Portal or run sp_set_firewall_rule on the master database to create a firewall rule for this IP address or address range.  It may take up to five minutes for this change to take effect. (40615) (SQLDriverConnect); [42000] [Microsoft][ODBC Driver 17 for SQL Server][SQL Server]Cannot open server 'article-server' requested by the login. Client with IP address '103.199.33.200' is not allowed to access the server.  To enable access, use the Azure Management Portal or run sp_set_firewall_rule on the master database to create a firewall rule for this IP address or address range.  It may take up to five minutes for this change to take effect. (40615)")
(Background on this error at: http://sqlalche.me/e/f405)
